Workbook

Sheet 📊 Resumen
C1: IREMI REMESAS RESUMEN GENERAL
A5: Mes | B5: Ops SELL | C5: Ops BUY | D5: Vol. CLP | E5: Gan. Bruta | F5: Gastos | G5: Gan. Neta
A6: Ago 2025 | B6: =COUNTIF('Agosto 2025'!B2:B61,"SELL") | C6: =COUNTIF('Agosto 2025'!B2:B61,"BUY") | D6: =SUMIF('Agosto 2025'!B2:B61,"SELL",'Agosto 2025'!D2:D61) | E6: =SUMIF('Agosto 2025'!B2:B61,"SELL",'Agosto 2025'!R2:R61) | F6: =SUMIF('💰 Gastos'!B3:B59,"Ago-25",'💰 Gastos'!E3:E59) | G6: =E6-F6
A7: Sep 2025 | B7: =COUNTIF('Septiembre 2025'!B2:B104,"SELL") | C7: =COUNTIF('Septiembre 2025'!B2:B104,"BUY") | D7: =SUMIF('Septiembre 2025'!B2:B104,"SELL",'Septiembre 2025'!D2:D104) | E7: =SUMIF('Septiembre 2025'!B2:B104,"SELL",'Septiembre 2025'!R2:R104) | F7: =SUMIF('💰 Gastos'!B3:B59,"Sep-25",'💰 Gastos'!E3:E59) | G7: =E7-F7
A8: Oct 2025 | B8: =COUNTIF('Octubre 2025'!B2:B110,"SELL") | C8: =COUNTIF('Octubre 2025'!B2:B110,"BUY") | D8: =SUMIF('Octubre 2025'!B2:B110,"SELL",'Octubre 2025'!D2:D110) | E8: =SUMIF('Octubre 2025'!B2:B110,"SELL",'Octubre 2025'!R2:R110) | F8: =SUMIF('💰 Gastos'!B3:B59,"Oct-25",'💰 Gastos'!E3:E59) | G8: =E8-F8
A9: Nov 2025 | B9: =COUNTIF('Noviembre 2025'!B2:B126,"SELL") | C9: =COUNTIF('Noviembre 2025'!B2:B126,"BUY") | D9: =SUMIF('Noviembre 2025'!B2:B126,"SELL",'Noviembre 2025'!D2:D126) | E9: =SUMIF('Noviembre 2025'!B2:B126,"SELL",'Noviembre 2025'!R2:R126) | F9: =SUMIF('💰 Gastos'!B3:B59,"Nov-25",'💰 Gastos'!E3:E59) | G9: =E9-F9
A10: Dic 2025 | B10: =COUNTIF('Diciembre 2025'!B2:B161,"SELL") | C10: =COUNTIF('Diciembre 2025'!B2:B161,"BUY") | D10: =SUMIF('Diciembre 2025'!B2:B161,"SELL",'Diciembre 2025'!D2:D161) | E10: =SUMIF('Diciembre 2025'!B2:B161,"SELL",'Diciembre 2025'!R2:R161) | F10: =SUMIF('💰 Gastos'!B3:B59,"Dic-25",'💰 Gastos'!E3:E59) | G10: =E10-F10
A11: Ene 2026 | B11: =COUNTIF('Enero 2026'!B2:B163,"SELL") | C11: =COUNTIF('Enero 2026'!B2:B163,"BUY") | D11: =SUMIF('Enero 2026'!B2:B163,"SELL",'Enero 2026'!D2:D163) | E11: =SUMIF('Enero 2026'!B2:B163,"SELL",'Enero 2026'!R2:R163) | F11: =SUMIF('💰 Gastos'!B3:B59,"Ene-26",'💰 Gastos'!E3:E59) | G11: =E11-F11
A12: Feb 2026 | B12: =COUNTIF('Febrero 2026'!B2:B171,"SELL") | C12: =COUNTIF('Febrero 2026'!B2:B171,"BUY") | D12: =SUMIF('Febrero 2026'!B2:B171,"SELL",'Febrero 2026'!D2:D171) | E12: =SUMIF('Febrero 2026'!B2:B171,"SELL",'Febrero 2026'!R2:R171) | F12: =SUMIF('💰 Gastos'!B3:B59,"Feb-26",'💰 Gastos'!E3:E59) | G12: =E12-F12
A13: Mar 2026 | B13: =COUNTIF('Marzo 2026'!B2:B131,"SELL") | C13: =COUNTIF('Marzo 2026'!B2:B131,"BUY") | D13: =SUMIF('Marzo 2026'!B2:B131,"SELL",'Marzo 2026'!D2:D131) | E13: =SUMIF('Marzo 2026'!B2:B131,"SELL",'Marzo 2026'!R2:R131) | F13: =SUMIF('💰 Gastos'!B3:B59,"Mar-26",'💰 Gastos'!E3:E59) | G13: =E13-F13
A14: Abr 2026 | B14: =COUNTIF('Abril 2026'!B2:B201,"SELL") | C14: =COUNTIF('Abril 2026'!B2:B201,"BUY") | D14: =SUMIF('Abril 2026'!B2:B201,"SELL",'Abril 2026'!D2:D201) | E14: =SUMIF('Abril 2026'!B2:B201,"SELL",'Abril 2026'!R2:R201) | F14: =SUMIF('💰 Gastos'!B3:B59,"Abr-26",'💰 Gastos'!E3:E59) | G14: =E14-F14
A15: TOTAL | B15: =SUM(B6:B14) | C15: =SUM(C6:C14) | D15: =SUM(D6:D14) | E15: =SUM(E6:E14) | F15: =SUM(F6:F14) | G15: =SUM(G6:G14)

Sheet Agosto 2025
A1: N° | B1: Tipo | C1: Fecha | D1: Monto CLP | E1: USDT/CLP Compra | F1: USDT/CLP Venta | G1: USDT Mov | H1: Tax Binance | I1: Capital USDT | J1: Tasa Destino | K1: Tasa Real | L1: Tasa IREMI | M1: Valor Destino | N1: Comentario | O1: % G USDT | P1: % G CLP | Q1: Ganancia USDT | R1: Ganancia CLP | S1: Acumulado SELL
A2: 1 | B2: BUY | C2: 45855 | D2: 20000 | E2: 971.99 | G2: 20.576343 | I2: 72.208434 | K2: =IF(AND(B2="SELL",E2>0,J2<>""),J2/E2,0) | M2: =IF(AND(B2="SELL",L2>0),D2*L2,0) | N2: inyeccion | O2: =IF(AND(B2="SELL",G2<>0),Q2/ABS(G2),0) | P2: =IF(AND(B2="SELL",D2>0),R2/D2,0) | Q2: =IF(AND(B2="SELL",D2>0,E2>0),(D2/E2)+G2,0) | R2: =IF(B2="SELL",Q2*F2,0) | S2: =R2
A3: 2 | B3: BUY | C3: 45865 | D3: 50000 | E3: 968.39 | G3: 51.63209 | I3: 72.208434 | K3: =IF(AND(B3="SELL",E3>0,J3<>""),J3/E3,0) | M3: =IF(AND(B3="SELL",L3>0),D3*L3,0) | N3: Inyeccion Cambio Rosalys Correg | O3: =IF(AND(B3="SELL",G3<>0),Q3/ABS(G3),0) | P3: =IF(AND(B3="SELL",D3>0),R3/D3,0) | Q3: =IF(AND(B3="SELL",D3>0,E3>0),(D3/E3)+G3,0) | R3: =IF(B3="SELL",Q3*F3,0) | S3: =S2+R3
A4: 3 | B4: SELL | C4: 45867 | D4: 10000 | E4: 968.39 | G4: -10 | I4: 62.208434 | J4: 164.5 | K4: =IF(AND(B4="SELL",E4>0,J4<>""),J4/E4,0) | M4: =IF(AND(B4="SELL",L4>0),D4*L4,0) | N4: Cambio Prueba Jesus | O4: =IF(AND(B4="SELL",G4<>0),Q4/ABS(G4),0) | P4: =IF(AND(B4="SELL",D4>0),R4/D4,0) | Q4: =IF(AND(B4="SELL",D4>0,E4>0),(D4/E4)+G4,0) | R4: =IF(B4="SELL",Q4*F4,0) | S4: =S3+R4
A5: 4 | B5: SELL | C5: 45873 | D5: 40000 | E5: 968.39 | G5: -41.65 | I5: -0.01791 | J5: 168.3 | K5: =IF(AND(B5="SELL",E5>0,J5<>""),J5/E5,0) | M5: =IF(AND(B5="SELL",L5>0),D5*L5,0) | N5: Cambio Rosalys | O5: =IF(AND(B5="SELL",G5<>0),Q5/ABS(G5),0) | P5: =IF(AND(B5="SELL",D5>0),R5/D5,0) | Q5: =IF(AND(B5="SELL",D5>0,E5>0),(D5/E5)+G5,0) | R5: =IF(B5="SELL",Q5*F5,0) | S5: =S4+R5
A6: 5 | B6: BUY | C6: 45874 | D6: 100000 | E6: 970.02 | G6: 103.09066 | I6: 123.64909 | K6: =IF(AND(B6="SELL",E6>0,J6<>""),J6/E6,0) | M6: =IF(AND(B6="SELL",L6>0),D6*L6,0) | N6: inyeccion | O6: =IF(AND(B6="SELL",G6<>0),Q6/ABS(G6),0) | P6: =IF(AND(B6="SELL",D6>0),R6/D6,0) | Q6: =IF(AND(B6="SELL",D6>0,E6>0),(D6/E6)+G6,0) | R6: =IF(B6="SELL",Q6*F6,0) | S6: =S5+R6
A7: 6 | B7: SELL | C7: 45874 | D7: 50000 | G7: -51.54 | I7: 72.109092 | J7: 170.8 | K7: =IF(AND(B7="SELL",E7>0,J7<>""),J7/E7,0) | M7: =IF(AND(B7="SELL",L7>0),D7*L7,0) | N7: Cambio Sr Jesus 30 y 20 Rosalys | O7: =IF(AND(B7="SELL",G7<>0),Q7/ABS(G7),0) | P7: =IF(AND(B7="SELL",D7>0),R7/D7,0) | Q7: =IF(AND(B7="SELL",D7>0,E7>0),(D7/E7)+G7,0) | R7: =IF(B7="SELL",Q7*F7,0) | S7: =S6+R7
A8: 7 | B8: BUY | C8: 45874 | D8: 50000 | E8: 973.24 | G8: 51.374789 | I8: 123.48388 | K8: =IF(AND(B8="SELL",E8>0,J8<>""),J8/E8,0) | M8: =IF(AND(B8="SELL",L8>0),D8*L8,0) | N8: inyeccion Jancy | O8: =IF(AND(B8="SELL",G8<>0),Q8/ABS(G8),0) | P8: =IF(AND(B8="SELL",D8>0),R8/D8,0) | Q8: =IF(AND(B8="SELL",D8>0,E8>0),(D8/E8)+G8,0) | R8: =IF(B8="SELL",Q8*F8,0) | S8: =S7+R8
A9: 8 | B9: SELL | C9: 45874 | D9: 50000 | G9: -46.1999 | I9: 77.283981 | J9: 175.515 | K9: =IF(AND(B9="SELL",E9>0,J9<>""),J9/E9,0) | M9: =IF(AND(B9="SELL",L9>0),D9*L9,0) | N9: Cambio Sr Jesus Jancy | O9: =IF(AND(B9="SELL",G9<>0),Q9/ABS(G9),0) | P9: =IF(AND(B9="SELL",D9>0),R9/D9,0) | Q9: =IF(AND(B9="SELL",D9>0,E9>0),(D9/E9)+G9,0) | R9: =IF(B9="SELL",Q9*F9,0) | S9: =S8+R9
A10: 9 | B10: BUY | C10: 45875 | D10: 50000 | E10: 980.99 | G10: 50.968919 | I10: 128.2529 | K10: =IF(AND(B10="SELL",E10>0,J10<>""),J10/E10,0) | M10: =IF(AND(B10="SELL",L10>0),D10*L10,0) | O10: =IF(AND(B10="SELL",G10<>0),Q10/ABS(G10),0) | P10: =IF(AND(B10="SELL",D10>0),R10/D10,0) | Q10: =IF(AND(B10="SELL",D10>0,E10>0),(D10/E10)+G10,0) | R10: =IF(B10="SELL",Q10*F10,0) | S10: =S9+R10
A11: 10 | B11: BUY | C11: 45875 | D11: 50000 | E11: 982.32 | G11: 50.89991 | I11: 179.15281 | K11: =IF(AND(B11="SELL",E11>0,J11<>""),J11/E11,0) | M11: =IF(AND(B11="SELL",L11>0),D11*L11,0) | O11: =IF(AND(B11="SELL",G11<>0),Q11/ABS(G11),0) | P11: =IF(AND(B11="SELL",D11>0),R11/D11,0) | Q11: =IF(AND(B11="SELL",D11>0,E11>0),(D11/E11)+G11,0) | R11: =IF(B11="SELL",Q11*F11,0) | S11: =S10+R11
A12: 11 | B12: SELL | C12: 45877 | D12: 10000 | E12: 982.32 | G12: -9.85 | I12: 169.30281 | J12: 178.8 | K12: =IF(AND(B12="SELL",E12>0,J12<>""),J12/E12,0) | L12: 0.176 | M12: =IF(AND(B12="SELL",L12>0),D12*L12,0) | N12: Inicio IREMI - Cambio Angel | O12: =IF(AND(B12="SELL",G12<>0),Q12/ABS(G12),0) | P12: =IF(AND(B12="SELL",D12>0),R12/D12,0) | Q12: =IF(AND(B12="SELL",D12>0,E12>0),(D12/E12)+G12,0) | R12: =IF(B12="SELL",Q12*F12,0) | S12: =S11+R12
A13: 12 | B13: SELL | C13: 45878 | D13: 10000 | E13: 982.32 | G13: -9.98 | I13: 159.32281 | J13: 180.2 | K13: =IF(AND(B13="SELL",E13>0,J13<>""),J13/E13,0) | L13: 0.18 | M13: =IF(AND(B13="SELL",L13>0),D13*L13,0) | N13: cambio paula | O13: =IF(AND(B13="SELL",G13<>0),Q13/ABS(G13),0) | P13: =IF(AND(B13="SELL",D13>0),R13/D13,0) | Q13: =IF(AND(B13="SELL",D13>0,E13>0),(D13/E13)+G13,0) | R13: =IF(B13="SELL",Q13*F13,0) | S13: =S12+R13
A14: 13 | B14: SELL | C14: 45878 | D14: 60000 | E14: 982.32 | G14: -59.25 | I14: 100.07281 | J14: 182.5 | K14: =IF(AND(B14="SELL",E14>0,J14<>""),J14/E14,0) | L14: 0.18 | M14: =IF(AND(B14="SELL",L14>0),D14*L14,0) | N14: Cambio ucla | O14: =IF(AND(B14="SELL",G14<>0),Q14/ABS(G14),0) | P14: =IF(AND(B14="SELL",D14>0),R14/D14,0) | Q14: =IF(AND(B14="SELL",D14>0,E14>0),(D14/E14)+G14,0) | R14: =IF(B14="SELL",Q14*F14,0) | S14: =S13+R14
A15: 14 | B15: SELL | C15: 45878 | D15: 20000 | E15: 982.32 | G15: -19.53 | I15: 80.542811 | J15: 3.4181 | K15: =IF(AND(B15="SELL",E15>0,J15<>""),J15/E15,0) | L15: 0.0034 | M15: =IF(AND(B15="SELL",L15>0),D15*L15,0) | N15: Cambio armando a PEN | O15: =IF(AND(B15="SELL",G15<>0),Q15/ABS(G15),0) | P15: =IF(AND(B15="SELL",D15>0),R15/D15,0) | Q15: =IF(AND(B15="SELL",D15>0,E15>0),(D15/E15)+G15,0) | R15: =IF(B15="SELL",Q15*F15,0) | S15: =S14+R15
A16: 15 | B16: BUY | C16: 45879 | D16: 100000 | E16: 971.42 | G16: 102.94208 | I16: 183.48489 | K16: =IF(AND(B16="SELL",E16>0,J16<>""),J16/E16,0) | M16: =IF(AND(B16="SELL",L16>0),D16*L16,0) | O16: =IF(AND(B16="SELL",G16<>0),Q16/ABS(G16),0) | P16: =IF(AND(B16="SELL",D16>0),R16/D16,0) | Q16: =IF(AND(B16="SELL",D16>0,E16>0),(D16/E16)+G16,0) | R16: =IF(B16="SELL",Q16*F16,0) | S16: =S15+R16
A17: 16 | B17: SELL | C17: 45879 | D17: 40000 | E17: 971.42 | G17: -39.12 | I17: 144.36489 | J17: 182.511 | K17: =IF(AND(B17="SELL",E17>0,J17<>""),J17/E17,0) | L17: 0.1785 | M17: =IF(AND(B17="SELL",L17>0),D17*L17,0) | N17: Cambio Angel 2 | O17: =IF(AND(B17="SELL",G17<>0),Q17/ABS(G17),0) | P17: =IF(AND(B17="SELL",D17>0),R17/D17,0) | Q17: =IF(AND(B17="SELL",D17>0,E17>0),(D17/E17)+G17,0) | R17: =IF(B17="SELL",Q17*F17,0) | S17: =S16+R17
A18: 17 | B18: SELL | C18: 45879 | D18: 90000 | E18: 971.42 | G18: -89.95 | I18: 54.414895 | J18: 182.41 | K18: =IF(AND(B18="SELL",E18>0,J18<>""),J18/E18,0) | L18: 0.1823 | M18: =IF(AND(B18="SELL",L18>0),D18*L18,0) | N18: Cambio paula y rosalys | O18: =IF(AND(B18="SELL",G18<>0),Q18/ABS(G18),0) | P18: =IF(AND(B18="SELL",D18>0),R18/D18,0) | Q18: =IF(AND(B18="SELL",D18>0,E18>0),(D18/E18)+G18,0) | R18: =IF(B18="SELL",Q18*F18,0) | S18: =S17+R18
A19: 18 | B19: BUY | C19: 45879 | D19: 100000 | E19: 971.52 | G19: 102.93149 | I19: 157.34638 | K19: =IF(AND(B19="SELL",E19>0,J19<>""),J19/E19,0) | M19: =IF(AND(B19="SELL",L19>0),D19*L19,0) | O19: =IF(AND(B19="SELL",G19<>0),Q19/ABS(G19),0) | P19: =IF(AND(B19="SELL",D19>0),R19/D19,0) | Q19: =IF(AND(B19="SELL",D19>0,E19>0),(D19/E19)+G19,0) | R19: =IF(B19="SELL",Q19*F19,0) | S19: =S18+R19
A20: 19 | B20: SELL | C20: 45883 | D20: 40000 | E20: 971.52 | F20: 962.2 | G20: -40.13 | I20: 117.21638 | J20: 189.103 | K20: =IF(AND(B20="SELL",E20>0,J20<>""),J20/E20,0) | L20: 0.1895 | M20: =IF(AND(B20="SELL",L20>0),D20*L20,0) | N20: Cambio Yakari Rosalys | O20: =IF(AND(B20="SELL",G20<>0),Q20/ABS(G20),0) | P20: =IF(AND(B20="SELL",D20>0),R20/D20,0) | Q20: =IF(AND(B20="SELL",D20>0,E20>0),(D20/E20)+G20,0) | R20: =IF(B20="SELL",Q20*F20,0) | S20: =S19+R20
A21: 20 | B21: SELL | C21: 45885 | D21: 30000 | E21: 971.42 | F21: 972.5 | G21: -29.52 | I21: 159.69638 | J21: 190 | K21: =IF(AND(B21="SELL",E21>0,J21<>""),J21/E21,0) | L21: 0.187 | M21: =IF(AND(B21="SELL",L21>0),D21*L21,0) | N21: cambio paula | O21: =IF(AND(B21="SELL",G21<>0),Q21/ABS(G21),0) | P21: =IF(AND(B21="SELL",D21>0),R21/D21,0) | Q21: =IF(AND(B21="SELL",D21>0,E21>0),(D21/E21)+G21,0) | R21: =IF(B21="SELL",Q21*F21,0) | S21: =S20+R21
A22: 21 | B22: SELL | C22: 45885 | D22: 120000 | E22: 971.42 | F22: 972.5 | G22: -116.94 | I22: 22.180041 | J22: 191.3 | K22: =IF(AND(B22="SELL",E22>0,J22<>""),J22/E22,0) | L22: 0.187 | M22: =IF(AND(B22="SELL",L22>0),D22*L22,0) | N22: Cambio Angel 2 | O22: =IF(AND(B22="SELL",G22<>0),Q22/ABS(G22),0) | P22: =IF(AND(B22="SELL",D22>0),R22/D22,0) | Q22: =IF(AND(B22="SELL",D22>0,E22>0),(D22/E22)+G22,0) | R22: =IF(B22="SELL",Q22*F22,0) | S22: =S21+R22
A23: 22 | B23: SELL | C23: 45885 | D23: 10000 | E23: 971.42 | F23: 972.5 | G23: -9.95 | I23: 12.230041 | J23: 187.925 | K23: =IF(AND(B23="SELL",E23>0,J23<>""),J23/E23,0) | L23: 0.187 | M23: =IF(AND(B23="SELL",L23>0),D23*L23,0) | N23: Cambio Mama tia aracelis | O23: =IF(AND(B23="SELL",G23<>0),Q23/ABS(G23),0) | P23: =IF(AND(B23="SELL",D23>0),R23/D23,0) | Q23: =IF(AND(B23="SELL",D23>0,E23>0),(D23/E23)+G23,0) | R23: =IF(B23="SELL",Q23*F23,0) | S23: =S22+R23
A24: 23 | B24: BUY | C24: 45885 | D24: 150000 | E24: 972.28 | F24: 972.5 | G24: 154.52 | I24: 187.32638 | K24: =IF(AND(B24="SELL",E24>0,J24<>""),J24/E24,0) | M24: =IF(AND(B24="SELL",L24>0),D24*L24,0) | O24: =IF(AND(B24="SELL",G24<>0),Q24/ABS(G24),0) | P24: =IF(AND(B24="SELL",D24>0),R24/D24,0) | Q24: =IF(AND(B24="SELL",D24>0,E24>0),(D24/E24)+G24,0) | R24: =IF(B24="SELL",Q24*F24,0) | S24: =S23+R24
A25: 24 | B25: SELL | C25: 45885 | D25: 40000 | E25: 972.28 | F25: 972.5 | G25: -39.13 | I25: 127.62004 | J25: 191.4 | K25: =IF(AND(B25="SELL",E25>0,J25<>""),J25/E25,0) | L25: 0.187 | M25: =IF(AND(B25="SELL",L25>0),D25*L25,0) | N25: Cambio Mama | O25: =IF(AND(B25="SELL",G25<>0),Q25/ABS(G25),0) | P25: =IF(AND(B25="SELL",D25>0),R25/D25,0) | Q25: =IF(AND(B25="SELL",D25>0,E25>0),(D25/E25)+G25,0) | R25: =IF(B25="SELL",Q25*F25,0) | S25: =S24+R25
A26: 25 | B26: SELL | C26: 45887 | D26: 500000 | E26: 970.7 | F26: 972.5 | G26: -450.5 | I26: -302.30362 | J26: 17.89 | K26: =IF(AND(B26="SELL",E26>0,J26<>""),J26/E26,0) | L26: 0.0174 | M26: =IF(AND(B26="SELL",L26>0),D26*L26,0) | N26: cambio johan a mxn | O26: =IF(AND(B26="SELL",G26<>0),Q26/ABS(G26),0) | P26: =IF(AND(B26="SELL",D26>0),R26/D26,0) | Q26: =IF(AND(B26="SELL",D26>0,E26>0),(D26/E26)+G26,0) | R26: =IF(B26="SELL",Q26*F26,0) | S26: =S25+R26
A27: 26 | B27: BUY | C27: 45887 | D27: 500000 | E27: 970.7 | F27: 972.5 | G27: 515.0922 | I27: 212.78859 | K27: =IF(AND(B27="SELL",E27>0,J27<>""),J27/E27,0) | M27: =IF(AND(B27="SELL",L27>0),D27*L27,0) | O27: =IF(AND(B27="SELL",G27<>0),Q27/ABS(G27),0) | P27: =IF(AND(B27="SELL",D27>0),R27/D27,0) | Q27: =IF(AND(B27="SELL",D27>0,E27>0),(D27/E27)+G27,0) | R27: =IF(B27="SELL",Q27*F27,0) | S27: =S26+R27
A28: 27 | B28: SELL | C28: 45889 | D28: 50000 | E28: 970.7 | F28: 969.94 | G28: -47.67 | I28: 165.11859 | J28: 209.106 | K28: =IF(AND(B28="SELL",E28>0,J28<>""),J28/E28,0) | L28: 0.199 | M28: =IF(AND(B28="SELL",L28>0),D28*L28,0) | N28: cambio pinky | O28: =IF(AND(B28="SELL",G28<>0),Q28/ABS(G28),0) | P28: =IF(AND(B28="SELL",D28>0),R28/D28,0) | Q28: =IF(AND(B28="SELL",D28>0,E28>0),(D28/E28)+G28,0) | R28: =IF(B28="SELL",Q28*F28,0) | S28: =S27+R28
A29: 28 | B29: SELL | C29: 45891 | D29: 30000 | E29: 970.7 | F29: 969.94 | G29: -30.46 | I29: 134.65859 | J29: 213.385 | K29: =IF(AND(B29="SELL",E29>0,J29<>""),J29/E29,0) | L29: 0.2175 | M29: =IF(AND(B29="SELL",L29>0),D29*L29,0) | N29: Cambio Turale | O29: =IF(AND(B29="SELL",G29<>0),Q29/ABS(G29),0) | P29: =IF(AND(B29="SELL",D29>0),R29/D29,0) | Q29: =IF(AND(B29="SELL",D29>0,E29>0),(D29/E29)+G29,0) | R29: =IF(B29="SELL",Q29*F29,0) | S29: =S28+R29
A30: 29 | B30: SELL | C30: 45891 | D30: 30000 | E30: 970.7 | F30: 969.94 | G30: -30.5 | I30: 104.15859 | J30: 213.1 | K30: =IF(AND(B30="SELL",E30>0,J30<>""),J30/E30,0) | L30: 0.2175 | M30: =IF(AND(B30="SELL",L30>0),D30*L30,0) | N30: Cambio paula ucla | O30: =IF(AND(B30="SELL",G30<>0),Q30/ABS(G30),0) | P30: =IF(AND(B30="SELL",D30>0),R30/D30,0) | Q30: =IF(AND(B30="SELL",D30>0,E30>0),(D30/E30)+G30,0) | R30: =IF(B30="SELL",Q30*F30,0) | S30: =S29+R30
A31: 30 | B31: SELL | C31: 45892 | D31: 20000 | E31: 970.7 | F31: 969.94 | G31: -19.93 | I31: 84.228586 | J31: 206.65 | K31: =IF(AND(B31="SELL",E31>0,J31<>""),J31/E31,0) | L31: 0.207 | M31: =IF(AND(B31="SELL",L31>0),D31*L31,0) | N31: Cambio Angel 2 | O31: =IF(AND(B31="SELL",G31<>0),Q31/ABS(G31),0) | P31: =IF(AND(B31="SELL",D31>0),R31/D31,0) | Q31: =IF(AND(B31="SELL",D31>0,E31>0),(D31/E31)+G31,0) | R31: =IF(B31="SELL",Q31*F31,0) | S31: =S30+R31
A32: 31 | B32: SELL | C32: 45892 | D32: 25000 | E32: 970.7 | F32: 969.94 | G32: -24.93 | I32: 59.298586 | J32: 206.5 | K32: =IF(AND(B32="SELL",E32>0,J32<>""),J32/E32,0) | L32: 0.207 | M32: =IF(AND(B32="SELL",L32>0),D32*L32,0) | N32: cambio pinky | O32: =IF(AND(B32="SELL",G32<>0),Q32/ABS(G32),0) | P32: =IF(AND(B32="SELL",D32>0),R32/D32,0) | Q32: =IF(AND(B32="SELL",D32>0,E32>0),(D32/E32)+G32,0) | R32: =IF(B32="SELL",Q32*F32,0) | S32: =S31+R32
A33: 32 | B33: SELL | C33: 45892 | D33: 31250 | E33: 970.7 | F33: 969.94 | G33: -30.55 | I33: 28.748586 | J33: 3926.97 | K33: =IF(AND(B33="SELL",E33>0,J33<>""),J33/E33,0) | L33: 3.84 | M33: =IF(AND(B33="SELL",L33>0),D33*L33,0) | N33: cambio angel Col | O33: =IF(AND(B33="SELL",G33<>0),Q33/ABS(G33),0) | P33: =IF(AND(B33="SELL",D33>0),R33/D33,0) | Q33: =IF(AND(B33="SELL",D33>0,E33>0),(D33/E33)+G33,0) | R33: =IF(B33="SELL",Q33*F33,0) | S33: =S32+R33
A34: 33 | B34: BUY | D34: 220000 | E34: 962.96 | F34: 962.96 | G34: 228.46 | I34: 257.20859 | K34: =IF(AND(B34="SELL",E34>0,J34<>""),J34/E34,0) | M34: =IF(AND(B34="SELL",L34>0),D34*L34,0) | O34: =IF(AND(B34="SELL",G34<>0),Q34/ABS(G34),0) | P34: =IF(AND(B34="SELL",D34>0),R34/D34,0) | Q34: =IF(AND(B34="SELL",D34>0,E34>0),(D34/E34)+G34,0) | R34: =IF(B34="SELL",Q34*F34,0) | S34: =S33+R34
A35: 34 | B35: SELL | C35: 45893 | D35: 30000 | E35: 962.96 | F35: 962.96 | G35: -29.466 | I35: 227.74259 | J35: 208.7 | K35: =IF(AND(B35="SELL",E35>0,J35<>""),J35/E35,0) | L35: 0.205 | M35: =IF(AND(B35="SELL",L35>0),D35*L35,0) | N35: cambio angel | O35: =IF(AND(B35="SELL",G35<>0),Q35/ABS(G35),0) | P35: =IF(AND(B35="SELL",D35>0),R35/D35,0) | Q35: =IF(AND(B35="SELL",D35>0,E35>0),(D35/E35)+G35,0) | R35: =IF(B35="SELL",Q35*F35,0) | S35: =S34+R35
A36: 35 | B36: SELL | C36: 45893 | D36: 30000 | E36: 962.96 | F36: 962.96 | G36: -29.466 | I36: 198.27659 | J36: 208.7 | K36: =IF(AND(B36="SELL",E36>0,J36<>""),J36/E36,0) | L36: 0.205 | M36: =IF(AND(B36="SELL",L36>0),D36*L36,0) | N36: cambio paula jesus | O36: =IF(AND(B36="SELL",G36<>0),Q36/ABS(G36),0) | P36: =IF(AND(B36="SELL",D36>0),R36/D36,0) | Q36: =IF(AND(B36="SELL",D36>0,E36>0),(D36/E36)+G36,0) | R36: =IF(B36="SELL",Q36*F36,0) | S36: =S35+R36
A37: 36 | B37: SELL | C37: 45893 | D37: 40000 | E37: 962.96 | F37: 962.96 | G37: -39.88 | I37: 158.39659 | J37: 208.7 | K37: =IF(AND(B37="SELL",E37>0,J37<>""),J37/E37,0) | L37: 0.205 | M37: =IF(AND(B37="SELL",L37>0),D37*L37,0) | N37: cambio mama | O37: =IF(AND(B37="SELL",G37<>0),Q37/ABS(G37),0) | P37: =IF(AND(B37="SELL",D37>0),R37/D37,0) | Q37: =IF(AND(B37="SELL",D37>0,E37>0),(D37/E37)+G37,0) | R37: =IF(B37="SELL",Q37*F37,0) | S37: =S36+R37
A38: 37 | B38: BUY | C38: 45893 | D38: 106500 | E38: 960.79 | F38: 960.79 | G38: 110.78 | I38: 269.17659 | K38: =IF(AND(B38="SELL",E38>0,J38<>""),J38/E38,0) | M38: =IF(AND(B38="SELL",L38>0),D38*L38,0) | O38: =IF(AND(B38="SELL",G38<>0),Q38/ABS(G38),0) | P38: =IF(AND(B38="SELL",D38>0),R38/D38,0) | Q38: =IF(AND(B38="SELL",D38>0,E38>0),(D38/E38)+G38,0) | R38: =IF(B38="SELL",Q38*F38,0) | S38: =S37+R38
A39: 38 | B39: SELL | C39: 45895 | D39: 20000 | E39: 960.79 | F39: 960.79 | G39: -19.88 | I39: 249.29659 | J39: 3.42 | K39: =IF(AND(B39="SELL",E39>0,J39<>""),J39/E39,0) | L39: 0.0034 | M39: =IF(AND(B39="SELL",L39>0),D39*L39,0) | N39: cambio oshetrup | O39: =IF(AND(B39="SELL",G39<>0),Q39/ABS(G39),0) | P39: =IF(AND(B39="SELL",D39>0),R39/D39,0) | Q39: =IF(AND(B39="SELL",D39>0,E39>0),(D39/E39)+G39,0) | R39: =IF(B39="SELL",Q39*F39,0) | S39: =S38+R39
A40: 39 | B40: SELL | C40: 45896 | D40: 30000 | E40: 960.79 | F40: 960.79 | G40: -29.54 | I40: 219.75659 | J40: 215.301 | K40: =IF(AND(B40="SELL",E40>0,J40<>""),J40/E40,0) | L40: 0.212 | M40: =IF(AND(B40="SELL",L40>0),D40*L40,0) | N40: cambio zulehyka | O40: =IF(AND(B40="SELL",G40<>0),Q40/ABS(G40),0) | P40: =IF(AND(B40="SELL",D40>0),R40/D40,0) | Q40: =IF(AND(B40="SELL",D40>0,E40>0),(D40/E40)+G40,0) | R40: =IF(B40="SELL",Q40*F40,0) | S40: =S39+R40
...

Sheet Septiembre 2025
A1: N° | B1: Tipo | C1: Fecha | D1: Monto CLP | E1: USDT/CLP Compra | F1: USDT/CLP Venta | G1: USDT Mov | H1: Tax Binance | I1: Capital USDT | J1: Tasa Destino | K1: Tasa Real | L1: Tasa IREMI | M1: Valor Destino | N1: Comentario | O1: % G USDT | P1: % G CLP | Q1: Ganancia USDT | R1: Ganancia CLP | S1: Acumulado SELL
A2: 1 | B2: BUY | C2: 45901 | D2: 300000 | E2: 970 | F2: 970 | G2: 309.27 | I2: 329.61659 | K2: =IF(AND(B2="SELL",E2>0,J2<>""),J2/E2,0) | M2: =IF(AND(B2="SELL",L2>0),D2*L2,0) | O2: =IF(AND(B2="SELL",G2<>0),Q2/ABS(G2),0) | P2: =IF(AND(B2="SELL",D2>0),R2/D2,0) | Q2: =IF(AND(B2="SELL",D2>0,E2>0),(D2/E2)+G2,0) | R2: =IF(B2="SELL",Q2*F2,0) | S2: ='Agosto 2025'!S61+R2
A3: 2 | B3: SELL | C3: 45901 | D3: 15000 | E3: 970 | F3: 970 | G3: -15.01 | I3: 314.60659 | J3: 200.45 | K3: =IF(AND(B3="SELL",E3>0,J3<>""),J3/E3,0) | L3: 0.2 | M3: =IF(AND(B3="SELL",L3>0),D3*L3,0) | N3: cambio paula | O3: =IF(AND(B3="SELL",G3<>0),Q3/ABS(G3),0) | P3: =IF(AND(B3="SELL",D3>0),R3/D3,0) | Q3: =IF(AND(B3="SELL",D3>0,E3>0),(D3/E3)+G3,0) | R3: =IF(B3="SELL",Q3*F3,0) | S3: =S2+R3
A4: 3 | B4: SELL | C4: 45901 | D4: 200000 | E4: 970 | F4: 970 | G4: -191.9 | I4: 122.70659 | J4: 0.86 | K4: =IF(AND(B4="SELL",E4>0,J4<>""),J4/E4,0) | L4: 0.000825 | M4: =IF(AND(B4="SELL",L4>0),D4*L4,0) | N4: cambio okunkule | O4: =IF(AND(B4="SELL",G4<>0),Q4/ABS(G4),0) | P4: =IF(AND(B4="SELL",D4>0),R4/D4,0) | Q4: =IF(AND(B4="SELL",D4>0,E4>0),(D4/E4)+G4,0) | R4: =IF(B4="SELL",Q4*F4,0) | S4: =S3+R4
A5: 4 | B5: SELL | C5: 45902 | D5: 60000 | E5: 970 | F5: 970 | G5: -58.81 | I5: 63.896586 | J5: 209.3 | K5: =IF(AND(B5="SELL",E5>0,J5<>""),J5/E5,0) | L5: 0.205 | M5: =IF(AND(B5="SELL",L5>0),D5*L5,0) | N5: cambio zuleyka | O5: =IF(AND(B5="SELL",G5<>0),Q5/ABS(G5),0) | P5: =IF(AND(B5="SELL",D5>0),R5/D5,0) | Q5: =IF(AND(B5="SELL",D5>0,E5>0),(D5/E5)+G5,0) | R5: =IF(B5="SELL",Q5*F5,0) | S5: =S4+R5
A6: 5 | B6: SELL | C6: 45902 | D6: 65000 | E6: 970 | F6: 970 | G6: -63.81 | I6: 0.0865857 | J6: 208.8 | K6: =IF(AND(B6="SELL",E6>0,J6<>""),J6/E6,0) | L6: 0.205 | M6: =IF(AND(B6="SELL",L6>0),D6*L6,0) | N6: cmabio yaka | O6: =IF(AND(B6="SELL",G6<>0),Q6/ABS(G6),0) | P6: =IF(AND(B6="SELL",D6>0),R6/D6,0) | Q6: =IF(AND(B6="SELL",D6>0,E6>0),(D6/E6)+G6,0) | R6: =IF(B6="SELL",Q6*F6,0) | S6: =S5+R6
A7: 6 | B7: BUY | C7: 45902 | D7: 340000 | E7: 978.3 | F7: 978.3 | G7: 347.54 | I7: 347.62659 | K7: =IF(AND(B7="SELL",E7>0,J7<>""),J7/E7,0) | M7: =IF(AND(B7="SELL",L7>0),D7*L7,0) | O7: =IF(AND(B7="SELL",G7<>0),Q7/ABS(G7),0) | P7: =IF(AND(B7="SELL",D7>0),R7/D7,0) | Q7: =IF(AND(B7="SELL",D7>0,E7>0),(D7/E7)+G7,0) | R7: =IF(B7="SELL",Q7*F7,0) | S7: =S6+R7
A8: 7 | B8: SELL | C8: 45902 | D8: 59000 | E8: 978.3 | F8: 978.3 | G8: -57.58 | I8: 290.04659 | J8: 209.0225 | K8: =IF(AND(B8="SELL",E8>0,J8<>""),J8/E8,0) | L8: 0.204 | M8: =IF(AND(B8="SELL",L8>0),D8*L8,0) | N8: cambio pinky | O8: =IF(AND(B8="SELL",G8<>0),Q8/ABS(G8),0) | P8: =IF(AND(B8="SELL",D8>0),R8/D8,0) | Q8: =IF(AND(B8="SELL",D8>0,E8>0),(D8/E8)+G8,0) | R8: =IF(B8="SELL",Q8*F8,0) | S8: =S7+R8
A9: 8 | B9: SELL | C9: 45902 | D9: 120000 | E9: 978.3 | F9: 978.3 | G9: -116.25 | I9: 173.79659 | J9: 211.7 | K9: =IF(AND(B9="SELL",E9>0,J9<>""),J9/E9,0) | L9: 0.205 | M9: =IF(AND(B9="SELL",L9>0),D9*L9,0) | N9: cambio francisco y jasniel | O9: =IF(AND(B9="SELL",G9<>0),Q9/ABS(G9),0) | P9: =IF(AND(B9="SELL",D9>0),R9/D9,0) | Q9: =IF(AND(B9="SELL",D9>0,E9>0),(D9/E9)+G9,0) | R9: =IF(B9="SELL",Q9*F9,0) | S9: =S8+R9
A10: 9 | B10: SELL | C10: 45902 | D10: 40000 | E10: 978.3 | F10: 978.3 | G10: -39.06 | I10: 134.73659 | J10: 210.2 | K10: =IF(AND(B10="SELL",E10>0,J10<>""),J10/E10,0) | L10: 0.205 | M10: =IF(AND(B10="SELL",L10>0),D10*L10,0) | N10: cambio para mi tia yari | O10: =IF(AND(B10="SELL",G10<>0),Q10/ABS(G10),0) | P10: =IF(AND(B10="SELL",D10>0),R10/D10,0) | Q10: =IF(AND(B10="SELL",D10>0,E10>0),(D10/E10)+G10,0) | R10: =IF(B10="SELL",Q10*F10,0) | S10: =S9+R10
A11: 10 | B11: BUY | C11: 45902 | D11: 400000 | E11: 979.3 | F11: 979.3 | G11: 408.45 | I11: 543.18659 | K11: =IF(AND(B11="SELL",E11>0,J11<>""),J11/E11,0) | M11: =IF(AND(B11="SELL",L11>0),D11*L11,0) | O11: =IF(AND(B11="SELL",G11<>0),Q11/ABS(G11),0) | P11: =IF(AND(B11="SELL",D11>0),R11/D11,0) | Q11: =IF(AND(B11="SELL",D11>0,E11>0),(D11/E11)+G11,0) | R11: =IF(B11="SELL",Q11*F11,0) | S11: =S10+R11
A12: 11 | B12: SELL | C12: 45902 | D12: 175707 | E12: 979.3 | F12: 979.3 | G12: -171.2 | I12: 371.98659 | J12: 212.61 | K12: =IF(AND(B12="SELL",E12>0,J12<>""),J12/E12,0) | L12: 0.205 | M12: =IF(AND(B12="SELL",L12>0),D12*L12,0) | N12: cambio zule y mi mama | O12: =IF(AND(B12="SELL",G12<>0),Q12/ABS(G12),0) | P12: =IF(AND(B12="SELL",D12>0),R12/D12,0) | Q12: =IF(AND(B12="SELL",D12>0,E12>0),(D12/E12)+G12,0) | R12: =IF(B12="SELL",Q12*F12,0) | S12: =S11+R12
A13: 12 | B13: SELL | C13: 45903 | D13: 29140 | E13: 979.3 | F13: 979.3 | G13: -28.72 | I13: 343.26659 | J13: 210 | K13: =IF(AND(B13="SELL",E13>0,J13<>""),J13/E13,0) | L13: 0.206 | M13: =IF(AND(B13="SELL",L13>0),D13*L13,0) | N13: cambio zule | O13: =IF(AND(B13="SELL",G13<>0),Q13/ABS(G13),0) | P13: =IF(AND(B13="SELL",D13>0),R13/D13,0) | Q13: =IF(AND(B13="SELL",D13>0,E13>0),(D13/E13)+G13,0) | R13: =IF(B13="SELL",Q13*F13,0) | S13: =S12+R13
A14: 13 | B14: SELL | C14: 45903 | D14: 20000 | E14: 979.3 | F14: 979.3 | G14: -19.61 | I14: 323.65659 | J14: 210 | K14: =IF(AND(B14="SELL",E14>0,J14<>""),J14/E14,0) | L14: 0.206 | M14: =IF(AND(B14="SELL",L14>0),D14*L14,0) | O14: =IF(AND(B14="SELL",G14<>0),Q14/ABS(G14),0) | P14: =IF(AND(B14="SELL",D14>0),R14/D14,0) | Q14: =IF(AND(B14="SELL",D14>0,E14>0),(D14/E14)+G14,0) | R14: =IF(B14="SELL",Q14*F14,0) | S14: =S13+R14
A15: 14 | B15: SELL | C15: 45903 | D15: 40000 | E15: 979.3 | F15: 979.3 | G15: -38.46 | I15: 285.19659 | J15: 214.22 | K15: =IF(AND(B15="SELL",E15>0,J15<>""),J15/E15,0) | L15: 0.206 | M15: =IF(AND(B15="SELL",L15>0),D15*L15,0) | O15: =IF(AND(B15="SELL",G15<>0),Q15/ABS(G15),0) | P15: =IF(AND(B15="SELL",D15>0),R15/D15,0) | Q15: =IF(AND(B15="SELL",D15>0,E15>0),(D15/E15)+G15,0) | R15: =IF(B15="SELL",Q15*F15,0) | S15: =S14+R15
A16: 15 | B16: SELL | C16: 45903 | D16: 17504 | E16: 979.3 | F16: 979.3 | G16: -17.07 | I16: 268.12659 | J16: 211.15 | K16: =IF(AND(B16="SELL",E16>0,J16<>""),J16/E16,0) | L16: 0.206 | M16: =IF(AND(B16="SELL",L16>0),D16*L16,0) | O16: =IF(AND(B16="SELL",G16<>0),Q16/ABS(G16),0) | P16: =IF(AND(B16="SELL",D16>0),R16/D16,0) | Q16: =IF(AND(B16="SELL",D16>0,E16>0),(D16/E16)+G16,0) | R16: =IF(B16="SELL",Q16*F16,0) | S16: =S15+R16
A17: 16 | B17: SELL | C17: 45903 | D17: 20000 | E17: 979.3 | F17: 979.3 | G17: -19.13 | I17: 248.99659 | J17: 215.34 | K17: =IF(AND(B17="SELL",E17>0,J17<>""),J17/E17,0) | L17: 0.206 | M17: =IF(AND(B17="SELL",L17>0),D17*L17,0) | O17: =IF(AND(B17="SELL",G17<>0),Q17/ABS(G17),0) | P17: =IF(AND(B17="SELL",D17>0),R17/D17,0) | Q17: =IF(AND(B17="SELL",D17>0,E17>0),(D17/E17)+G17,0) | R17: =IF(B17="SELL",Q17*F17,0) | S17: =S16+R17
A18: 17 | B18: SELL | C18: 45904 | D18: 15000 | E18: 979.3 | F18: 979.3 | G18: -14.64 | I18: 234.35659 | J18: 215.05 | K18: =IF(AND(B18="SELL",E18>0,J18<>""),J18/E18,0) | L18: 0.207 | M18: =IF(AND(B18="SELL",L18>0),D18*L18,0) | N18: cambio paula sra | O18: =IF(AND(B18="SELL",G18<>0),Q18/ABS(G18),0) | P18: =IF(AND(B18="SELL",D18>0),R18/D18,0) | Q18: =IF(AND(B18="SELL",D18>0,E18>0),(D18/E18)+G18,0) | R18: =IF(B18="SELL",Q18*F18,0) | S18: =S17+R18
A19: 18 | B19: SELL | C19: 45904 | D19: 30000 | E19: 979.3 | F19: 979.3 | G19: -29.13 | I19: 205.22659 | J19: 3912.17 | K19: =IF(AND(B19="SELL",E19>0,J19<>""),J19/E19,0) | L19: 3.8 | M19: =IF(AND(B19="SELL",L19>0),D19*L19,0) | N19: cambio turale | O19: =IF(AND(B19="SELL",G19<>0),Q19/ABS(G19),0) | P19: =IF(AND(B19="SELL",D19>0),R19/D19,0) | Q19: =IF(AND(B19="SELL",D19>0,E19>0),(D19/E19)+G19,0) | R19: =IF(B19="SELL",Q19*F19,0) | S19: =S18+R19
A20: 19 | B20: SELL | C20: 45905 | D20: 22000 | E20: 979.3 | F20: 979.3 | G20: -21.42 | I20: 183.80659 | J20: 214.701 | K20: =IF(AND(B20="SELL",E20>0,J20<>""),J20/E20,0) | L20: 0.209 | M20: =IF(AND(B20="SELL",L20>0),D20*L20,0) | O20: =IF(AND(B20="SELL",G20<>0),Q20/ABS(G20),0) | P20: =IF(AND(B20="SELL",D20>0),R20/D20,0) | Q20: =IF(AND(B20="SELL",D20>0,E20>0),(D20/E20)+G20,0) | R20: =IF(B20="SELL",Q20*F20,0) | S20: =S19+R20
A21: 20 | B21: SELL | C21: 45905 | D21: 10000 | E21: 979.3 | F21: 979.3 | G21: -9.86 | I21: 173.94659 | J21: 3853.5 | K21: =IF(AND(B21="SELL",E21>0,J21<>""),J21/E21,0) | L21: 3.8 | M21: =IF(AND(B21="SELL",L21>0),D21*L21,0) | N21: cambio turale | O21: =IF(AND(B21="SELL",G21<>0),Q21/ABS(G21),0) | P21: =IF(AND(B21="SELL",D21>0),R21/D21,0) | Q21: =IF(AND(B21="SELL",D21>0,E21>0),(D21/E21)+G21,0) | R21: =IF(B21="SELL",Q21*F21,0) | S21: =S20+R21
A22: 21 | B22: SELL | C22: 45906 | D22: 7000 | E22: 979.3 | F22: 979.3 | G22: -6.96 | I22: 166.98659 | J22: 210.057 | K22: =IF(AND(B22="SELL",E22>0,J22<>""),J22/E22,0) | L22: 0.209 | M22: =IF(AND(B22="SELL",L22>0),D22*L22,0) | N22: cambio wale | O22: =IF(AND(B22="SELL",G22<>0),Q22/ABS(G22),0) | P22: =IF(AND(B22="SELL",D22>0),R22/D22,0) | Q22: =IF(AND(B22="SELL",D22>0,E22>0),(D22/E22)+G22,0) | R22: =IF(B22="SELL",Q22*F22,0) | S22: =S21+R22
A23: 22 | B23: SELL | C23: 45906 | D23: 25667 | E23: 979.3 | F23: 979.3 | G23: -24.82 | I23: 142.16659 | J23: 217.105 | K23: =IF(AND(B23="SELL",E23>0,J23<>""),J23/E23,0) | L23: 0.2105 | M23: =IF(AND(B23="SELL",L23>0),D23*L23,0) | N23: pago de internet jesus | O23: =IF(AND(B23="SELL",G23<>0),Q23/ABS(G23),0) | P23: =IF(AND(B23="SELL",D23>0),R23/D23,0) | Q23: =IF(AND(B23="SELL",D23>0,E23>0),(D23/E23)+G23,0) | R23: =IF(B23="SELL",Q23*F23,0) | S23: =S22+R23
A24: 23 | B24: SELL | C24: 45906 | D24: 30000 | E24: 979.3 | F24: 979.3 | G24: -29.23 | I24: 112.93659 | J24: 216.019 | K24: =IF(AND(B24="SELL",E24>0,J24<>""),J24/E24,0) | L24: 0.2105 | M24: =IF(AND(B24="SELL",L24>0),D24*L24,0) | N24: cambio rosalys | O24: =IF(AND(B24="SELL",G24<>0),Q24/ABS(G24),0) | P24: =IF(AND(B24="SELL",D24>0),R24/D24,0) | Q24: =IF(AND(B24="SELL",D24>0,E24>0),(D24/E24)+G24,0) | R24: =IF(B24="SELL",Q24*F24,0) | S24: =S23+R24
A25: 24 | B25: SELL | C25: 45906 | D25: 50000 | E25: 979.3 | F25: 979.3 | G25: -48.56 | I25: 64.376586 | J25: 216.7 | K25: =IF(AND(B25="SELL",E25>0,J25<>""),J25/E25,0) | L25: 0.2105 | M25: =IF(AND(B25="SELL",L25>0),D25*L25,0) | N25: cambio pinky | O25: =IF(AND(B25="SELL",G25<>0),Q25/ABS(G25),0) | P25: =IF(AND(B25="SELL",D25>0),R25/D25,0) | Q25: =IF(AND(B25="SELL",D25>0,E25>0),(D25/E25)+G25,0) | R25: =IF(B25="SELL",Q25*F25,0) | S25: =S24+R25
A26: 25 | B26: SELL | C26: 45906 | D26: 50000 | E26: 979.3 | F26: 979.3 | G26: -48.54 | I26: 15.836586 | J26: 216.8 | K26: =IF(AND(B26="SELL",E26>0,J26<>""),J26/E26,0) | L26: 0.2105 | M26: =IF(AND(B26="SELL",L26>0),D26*L26,0) | N26: cambio rosalys | O26: =IF(AND(B26="SELL",G26<>0),Q26/ABS(G26),0) | P26: =IF(AND(B26="SELL",D26>0),R26/D26,0) | Q26: =IF(AND(B26="SELL",D26>0,E26>0),(D26/E26)+G26,0) | R26: =IF(B26="SELL",Q26*F26,0) | S26: =S25+R26
A27: 26 | B27: BUY | C27: 45906 | D27: 366000 | E27: 974.45 | F27: 974.45 | G27: 375.59 | I27: 391.42659 | K27: =IF(AND(B27="SELL",E27>0,J27<>""),J27/E27,0) | L27: 0.2105 | M27: =IF(AND(B27="SELL",L27>0),D27*L27,0) | O27: =IF(AND(B27="SELL",G27<>0),Q27/ABS(G27),0) | P27: =IF(AND(B27="SELL",D27>0),R27/D27,0) | Q27: =IF(AND(B27="SELL",D27>0,E27>0),(D27/E27)+G27,0) | R27: =IF(B27="SELL",Q27*F27,0) | S27: =S26+R27
A28: 27 | B28: SELL | C28: 45907 | D28: 50000 | E28: 979.3 | F28: 979.3 | G28: -49.04 | I28: 342.38659 | J28: 215.61 | K28: =IF(AND(B28="SELL",E28>0,J28<>""),J28/E28,0) | L28: 0.2115 | M28: =IF(AND(B28="SELL",L28>0),D28*L28,0) | N28: cambio mimi | O28: =IF(AND(B28="SELL",G28<>0),Q28/ABS(G28),0) | P28: =IF(AND(B28="SELL",D28>0),R28/D28,0) | Q28: =IF(AND(B28="SELL",D28>0,E28>0),(D28/E28)+G28,0) | R28: =IF(B28="SELL",Q28*F28,0) | S28: =S27+R28
A29: 28 | B29: SELL | C29: 45907 | D29: 30950 | E29: 979.3 | F29: 979.3 | G29: -30.6 | I29: 311.78659 | J29: 213 | K29: =IF(AND(B29="SELL",E29>0,J29<>""),J29/E29,0) | L29: 3.8 | M29: =IF(AND(B29="SELL",L29>0),D29*L29,0) | N29: cambio yumery | O29: =IF(AND(B29="SELL",G29<>0),Q29/ABS(G29),0) | P29: =IF(AND(B29="SELL",D29>0),R29/D29,0) | Q29: =IF(AND(B29="SELL",D29>0,E29>0),(D29/E29)+G29,0) | R29: =IF(B29="SELL",Q29*F29,0) | S29: =S28+R29
A30: 29 | B30: SELL | C30: 45908 | D30: 20000 | E30: 979.3 | F30: 979.3 | G30: -19.71 | I30: 292.07659 | J30: 213 | K30: =IF(AND(B30="SELL",E30>0,J30<>""),J30/E30,0) | L30: 0.2115 | M30: =IF(AND(B30="SELL",L30>0),D30*L30,0) | N30: cambio turale | O30: =IF(AND(B30="SELL",G30<>0),Q30/ABS(G30),0) | P30: =IF(AND(B30="SELL",D30>0),R30/D30,0) | Q30: =IF(AND(B30="SELL",D30>0,E30>0),(D30/E30)+G30,0) | R30: =IF(B30="SELL",Q30*F30,0) | S30: =S29+R30
A31: 30 | B31: SELL | C31: 45908 | D31: 43810 | E31: 979.3 | F31: 979.3 | G31: -41.75 | I31: 250.32659 | J31: 220.32 | K31: =IF(AND(B31="SELL",E31>0,J31<>""),J31/E31,0) | L31: 0.21 | M31: =IF(AND(B31="SELL",L31>0),D31*L31,0) | N31: cmabio paula | O31: =IF(AND(B31="SELL",G31<>0),Q31/ABS(G31),0) | P31: =IF(AND(B31="SELL",D31>0),R31/D31,0) | Q31: =IF(AND(B31="SELL",D31>0,E31>0),(D31/E31)+G31,0) | R31: =IF(B31="SELL",Q31*F31,0) | S31: =S30+R31
A32: 31 | B32: SELL | C32: 45908 | D32: 50000 | E32: 979.3 | F32: 979.3 | G32: -49.13 | I32: 201.19659 | J32: 3867 | K32: =IF(AND(B32="SELL",E32>0,J32<>""),J32/E32,0) | L32: 3.8 | M32: =IF(AND(B32="SELL",L32>0),D32*L32,0) | N32: cambio ramses | O32: =IF(AND(B32="SELL",G32<>0),Q32/ABS(G32),0) | P32: =IF(AND(B32="SELL",D32>0),R32/D32,0) | Q32: =IF(AND(B32="SELL",D32>0,E32>0),(D32/E32)+G32,0) | R32: =IF(B32="SELL",Q32*F32,0) | S32: =S31+R32
A33: 32 | B33: SELL | C33: 45908 | D33: 30000 | E33: 979.3 | F33: 979.3 | G33: -28.59 | I33: 172.60659 | J33: 220.3 | K33: =IF(AND(B33="SELL",E33>0,J33<>""),J33/E33,0) | L33: 0.21 | M33: =IF(AND(B33="SELL",L33>0),D33*L33,0) | N33: cambio rosalys | O33: =IF(AND(B33="SELL",G33<>0),Q33/ABS(G33),0) | P33: =IF(AND(B33="SELL",D33>0),R33/D33,0) | Q33: =IF(AND(B33="SELL",D33>0,E33>0),(D33/E33)+G33,0) | R33: =IF(B33="SELL",Q33*F33,0) | S33: =S32+R33
A34: 33 | B34: SELL | C34: 45909 | D34: 40000 | E34: 979.3 | F34: 979.3 | G34: -37.66 | I34: 177.94659 | J34: 232.6 | K34: =IF(AND(B34="SELL",E34>0,J34<>""),J34/E34,0) | L34: 0.219 | M34: =IF(AND(B34="SELL",L34>0),D34*L34,0) | N34: cambio | O34: =IF(AND(B34="SELL",G34<>0),Q34/ABS(G34),0) | P34: =IF(AND(B34="SELL",D34>0),R34/D34,0) | Q34: =IF(AND(B34="SELL",D34>0,E34>0),(D34/E34)+G34,0) | R34: =IF(B34="SELL",Q34*F34,0) | S34: =S33+R34
A35: 34 | B35: SELL | C35: 45910 | D35: 150000 | E35: 979.3 | F35: 979.3 | G35: -139.59 | I35: 38.356586 | J35: 238.006 | K35: =IF(AND(B35="SELL",E35>0,J35<>""),J35/E35,0) | L35: 0.2245 | M35: =IF(AND(B35="SELL",L35>0),D35*L35,0) | N35: cambio paula y pinky | O35: =IF(AND(B35="SELL",G35<>0),Q35/ABS(G35),0) | P35: =IF(AND(B35="SELL",D35>0),R35/D35,0) | Q35: =IF(AND(B35="SELL",D35>0,E35>0),(D35/E35)+G35,0) | R35: =IF(B35="SELL",Q35*F35,0) | S35: =S34+R35
A36: 35 | B36: SELL | C36: 45910 | D36: 5000 | E36: 979.3 | F36: 979.3 | G36: -5.27 | I36: 33.086586 | J36: 231.866 | K36: =IF(AND(B36="SELL",E36>0,J36<>""),J36/E36,0) | L36: 0.2245 | M36: =IF(AND(B36="SELL",L36>0),D36*L36,0) | N36: cambio pinky | O36: =IF(AND(B36="SELL",G36<>0),Q36/ABS(G36),0) | P36: =IF(AND(B36="SELL",D36>0),R36/D36,0) | Q36: =IF(AND(B36="SELL",D36>0,E36>0),(D36/E36)+G36,0) | R36: =IF(B36="SELL",Q36*F36,0) | S36: =S35+R36
A37: 36 | B37: BUY | C37: 45911 | D37: 507887 | E37: 964.77 | F37: 964.77 | G37: 526.43 | I37: 559.51659 | K37: =IF(AND(B37="SELL",E37>0,J37<>""),J37/E37,0) | M37: =IF(AND(B37="SELL",L37>0),D37*L37,0) | O37: =IF(AND(B37="SELL",G37<>0),Q37/ABS(G37),0) | P37: =IF(AND(B37="SELL",D37>0),R37/D37,0) | Q37: =IF(AND(B37="SELL",D37>0,E37>0),(D37/E37)+G37,0) | R37: =IF(B37="SELL",Q37*F37,0) | S37: =S36+R37
A38: 37 | B38: SELL | C38: 45911 | D38: 50000 | E38: 964.77 | F38: 964.77 | G38: -49.91 | I38: 509.60659 | J38: 238.4 | K38: =IF(AND(B38="SELL",E38>0,J38<>""),J38/E38,0) | L38: 0.238 | M38: =IF(AND(B38="SELL",L38>0),D38*L38,0) | N38: cambio paula | O38: =IF(AND(B38="SELL",G38<>0),Q38/ABS(G38),0) | P38: =IF(AND(B38="SELL",D38>0),R38/D38,0) | Q38: =IF(AND(B38="SELL",D38>0,E38>0),(D38/E38)+G38,0) | R38: =IF(B38="SELL",Q38*F38,0) | S38: =S37+R38
A39: 38 | B39: SELL | C39: 45911 | D39: 50000 | E39: 964.77 | F39: 964.77 | G39: -49.64 | I39: 459.96659 | J39: 18.53 | K39: =IF(AND(B39="SELL",E39>0,J39<>""),J39/E39,0) | L39: 0.184 | M39: =IF(AND(B39="SELL",L39>0),D39*L39,0) | N39: cambio paula | O39: =IF(AND(B39="SELL",G39<>0),Q39/ABS(G39),0) | P39: =IF(AND(B39="SELL",D39>0),R39/D39,0) | Q39: =IF(AND(B39="SELL",D39>0,E39>0),(D39/E39)+G39,0) | R39: =IF(B39="SELL",Q39*F39,0) | S39: =S38+R39
A40: 39 | B40: SELL | C40: 45911 | D40: 20000 | E40: 964.77 | F40: 964.77 | G40: -20.2 | I40: 439.76659 | J40: 235.601 | K40: =IF(AND(B40="SELL",E40>0,J40<>""),J40/E40,0) | L40: 0.238 | M40: =IF(AND(B40="SELL",L40>0),D40*L40,0) | N40: cambio wale | O40: =IF(AND(B40="SELL",G40<>0),Q40/ABS(G40),0) | P40: =IF(AND(B40="SELL",D40>0),R40/D40,0) | Q40: =IF(AND(B40="SELL",D40>0,E40>0),(D40/E40)+G40,0) | R40: =IF(B40="SELL",Q40*F40,0) | S40: =S39+R40
...

Sheet Octubre 2025
A1: N° | B1: Tipo | C1: Fecha | D1: Monto CLP | E1: USDT/CLP Compra | F1: USDT/CLP Venta | G1: USDT Mov | H1: Tax Binance | I1: Capital USDT | J1: Tasa Destino | K1: Tasa Real | L1: Tasa IREMI | M1: Valor Destino | N1: Comentario | O1: % G USDT | P1: % G CLP | Q1: Ganancia USDT | R1: Ganancia CLP | S1: Acumulado SELL
A2: 1 | B2: SELL | C2: 45930 | D2: 20000 | E2: 967 | F2: 967 | G2: -19.95 | I2: 375.03 | J2: 280.6 | K2: =IF(AND(B2="SELL",E2>0,J2<>""),J2/E2,0) | L2: 0.28 | M2: =IF(AND(B2="SELL",L2>0),D2*L2,0) | O2: =IF(AND(B2="SELL",G2<>0),Q2/ABS(G2),0) | P2: =IF(AND(B2="SELL",D2>0),R2/D2,0) | Q2: =IF(AND(B2="SELL",D2>0,E2>0),(D2/E2)+G2,0) | R2: =IF(B2="SELL",Q2*F2,0) | S2: ='Septiembre 2025'!S104+R2
A3: 2 | B3: SELL | C3: 45931 | D3: 165000 | E3: 967 | F3: 967 | G3: -162.92 | I3: 212.11 | J3: 285.2 | K3: =IF(AND(B3="SELL",E3>0,J3<>""),J3/E3,0) | L3: 0.278 | M3: =IF(AND(B3="SELL",L3>0),D3*L3,0) | N3: Cambio uvida y francisco | O3: =IF(AND(B3="SELL",G3<>0),Q3/ABS(G3),0) | P3: =IF(AND(B3="SELL",D3>0),R3/D3,0) | Q3: =IF(AND(B3="SELL",D3>0,E3>0),(D3/E3)+G3,0) | R3: =IF(B3="SELL",Q3*F3,0) | S3: =S2+R3
A4: 3 | B4: SELL | C4: 45931 | D4: 110000 | E4: 967 | F4: 967 | G4: -106.87 | I4: 105.24 | J4: 289.21 | K4: =IF(AND(B4="SELL",E4>0,J4<>""),J4/E4,0) | L4: 0.281 | M4: =IF(AND(B4="SELL",L4>0),D4*L4,0) | N4: cambio angel | O4: =IF(AND(B4="SELL",G4<>0),Q4/ABS(G4),0) | P4: =IF(AND(B4="SELL",D4>0),R4/D4,0) | Q4: =IF(AND(B4="SELL",D4>0,E4>0),(D4/E4)+G4,0) | R4: =IF(B4="SELL",Q4*F4,0) | S4: =S3+R4
A5: 4 | B5: SELL | C5: 45931 | D5: 100000 | E5: 967 | F5: 967 | G5: -97.48 | I5: 7.76 | J5: 288.25 | K5: =IF(AND(B5="SELL",E5>0,J5<>""),J5/E5,0) | L5: 0.281 | M5: =IF(AND(B5="SELL",L5>0),D5*L5,0) | O5: =IF(AND(B5="SELL",G5<>0),Q5/ABS(G5),0) | P5: =IF(AND(B5="SELL",D5>0),R5/D5,0) | Q5: =IF(AND(B5="SELL",D5>0,E5>0),(D5/E5)+G5,0) | R5: =IF(B5="SELL",Q5*F5,0) | S5: =S4+R5
A6: 5 | B6: BUY | C6: 45931 | D6: 1020000 | E6: 964.8 | F6: 964.8 | G6: 1057.21 | I6: 1064.97 | K6: =IF(AND(B6="SELL",E6>0,J6<>""),J6/E6,0) | M6: =IF(AND(B6="SELL",L6>0),D6*L6,0) | O6: =IF(AND(B6="SELL",G6<>0),Q6/ABS(G6),0) | P6: =IF(AND(B6="SELL",D6>0),R6/D6,0) | Q6: =IF(AND(B6="SELL",D6>0,E6>0),(D6/E6)+G6,0) | R6: =IF(B6="SELL",Q6*F6,0) | S6: =S5+R6
A7: 6 | B7: SELL | C7: 45931 | D7: 105000 | E7: 964.8 | F7: 964.8 | G7: -102.21 | I7: 962.76 | J7: 288.65 | K7: =IF(AND(B7="SELL",E7>0,J7<>""),J7/E7,0) | L7: 0.281 | M7: =IF(AND(B7="SELL",L7>0),D7*L7,0) | O7: =IF(AND(B7="SELL",G7<>0),Q7/ABS(G7),0) | P7: =IF(AND(B7="SELL",D7>0),R7/D7,0) | Q7: =IF(AND(B7="SELL",D7>0,E7>0),(D7/E7)+G7,0) | R7: =IF(B7="SELL",Q7*F7,0) | S7: =S6+R7
A8: 7 | B8: SELL | C8: 45931 | D8: 18000 | E8: 964.8 | F8: 964.8 | G8: -17.8 | I8: 944.96 | J8: 284.005 | K8: =IF(AND(B8="SELL",E8>0,J8<>""),J8/E8,0) | L8: 0.281 | M8: =IF(AND(B8="SELL",L8>0),D8*L8,0) | O8: =IF(AND(B8="SELL",G8<>0),Q8/ABS(G8),0) | P8: =IF(AND(B8="SELL",D8>0),R8/D8,0) | Q8: =IF(AND(B8="SELL",D8>0,E8>0),(D8/E8)+G8,0) | R8: =IF(B8="SELL",Q8*F8,0) | S8: =S7+R8
A9: 8 | B9: SELL | C9: 45932 | D9: 130000 | E9: 964.8 | F9: 964.8 | G9: -127.09 | I9: 817.87 | J9: 291.51 | K9: =IF(AND(B9="SELL",E9>0,J9<>""),J9/E9,0) | L9: 0.285 | M9: =IF(AND(B9="SELL",L9>0),D9*L9,0) | O9: =IF(AND(B9="SELL",G9<>0),Q9/ABS(G9),0) | P9: =IF(AND(B9="SELL",D9>0),R9/D9,0) | Q9: =IF(AND(B9="SELL",D9>0,E9>0),(D9/E9)+G9,0) | R9: =IF(B9="SELL",Q9*F9,0) | S9: =S8+R9
A10: 9 | B10: SELL | C10: 45932 | D10: 50000 | E10: 964.8 | F10: 964.8 | G10: -49.82 | I10: 768.05 | J10: 286 | K10: =IF(AND(B10="SELL",E10>0,J10<>""),J10/E10,0) | L10: 0.285 | M10: =IF(AND(B10="SELL",L10>0),D10*L10,0) | O10: =IF(AND(B10="SELL",G10<>0),Q10/ABS(G10),0) | P10: =IF(AND(B10="SELL",D10>0),R10/D10,0) | Q10: =IF(AND(B10="SELL",D10>0,E10>0),(D10/E10)+G10,0) | R10: =IF(B10="SELL",Q10*F10,0) | S10: =S9+R10
A11: 10 | B11: SELL | C11: 45932 | D11: 40000 | E11: 964.8 | F11: 964.8 | G11: -39.37 | I11: 728.68 | J11: 289.519 | K11: =IF(AND(B11="SELL",E11>0,J11<>""),J11/E11,0) | L11: 0.285 | M11: =IF(AND(B11="SELL",L11>0),D11*L11,0) | O11: =IF(AND(B11="SELL",G11<>0),Q11/ABS(G11),0) | P11: =IF(AND(B11="SELL",D11>0),R11/D11,0) | Q11: =IF(AND(B11="SELL",D11>0,E11>0),(D11/E11)+G11,0) | R11: =IF(B11="SELL",Q11*F11,0) | S11: =S10+R11
A12: 11 | B12: SELL | C12: 45932 | D12: 20000 | E12: 964.8 | F12: 964.8 | G12: -19.9 | I12: 708.78 | J12: 3421 | K12: =IF(AND(B12="SELL",E12>0,J12<>""),J12/E12,0) | L12: 0.0034 | M12: =IF(AND(B12="SELL",L12>0),D12*L12,0) | O12: =IF(AND(B12="SELL",G12<>0),Q12/ABS(G12),0) | P12: =IF(AND(B12="SELL",D12>0),R12/D12,0) | Q12: =IF(AND(B12="SELL",D12>0,E12>0),(D12/E12)+G12,0) | R12: =IF(B12="SELL",Q12*F12,0) | S12: =S11+R12
A13: 12 | B13: SELL | C13: 45933 | D13: 22000 | E13: 964.8 | F13: 964.8 | G13: -22.19 | I13: 686.59 | J13: 286.5 | K13: =IF(AND(B13="SELL",E13>0,J13<>""),J13/E13,0) | L13: 0.289 | M13: =IF(AND(B13="SELL",L13>0),D13*L13,0) | O13: =IF(AND(B13="SELL",G13<>0),Q13/ABS(G13),0) | P13: =IF(AND(B13="SELL",D13>0),R13/D13,0) | Q13: =IF(AND(B13="SELL",D13>0,E13>0),(D13/E13)+G13,0) | R13: =IF(B13="SELL",Q13*F13,0) | S13: =S12+R13
A14: 13 | B14: SELL | C14: 45933 | D14: 80000 | E14: 964.8 | F14: 964.8 | G14: -79.92 | I14: 606.67 | J14: 289.26 | K14: =IF(AND(B14="SELL",E14>0,J14<>""),J14/E14,0) | L14: 0.289 | M14: =IF(AND(B14="SELL",L14>0),D14*L14,0) | O14: =IF(AND(B14="SELL",G14<>0),Q14/ABS(G14),0) | P14: =IF(AND(B14="SELL",D14>0),R14/D14,0) | Q14: =IF(AND(B14="SELL",D14>0,E14>0),(D14/E14)+G14,0) | R14: =IF(B14="SELL",Q14*F14,0) | S14: =S13+R14
A15: 14 | B15: SELL | C15: 45933 | D15: 80000 | E15: 964.8 | F15: 964.8 | G15: -79.28 | I15: 527.39 | J15: 291.61 | K15: =IF(AND(B15="SELL",E15>0,J15<>""),J15/E15,0) | L15: 0.289 | M15: =IF(AND(B15="SELL",L15>0),D15*L15,0) | O15: =IF(AND(B15="SELL",G15<>0),Q15/ABS(G15),0) | P15: =IF(AND(B15="SELL",D15>0),R15/D15,0) | Q15: =IF(AND(B15="SELL",D15>0,E15>0),(D15/E15)+G15,0) | R15: =IF(B15="SELL",Q15*F15,0) | S15: =S14+R15
A16: 15 | B16: SELL | C16: 45933 | D16: 25000 | E16: 964.8 | F16: 964.8 | G16: -25.21 | I16: 502.18 | J16: 286 | K16: =IF(AND(B16="SELL",E16>0,J16<>""),J16/E16,0) | L16: 0.289 | M16: =IF(AND(B16="SELL",L16>0),D16*L16,0) | O16: =IF(AND(B16="SELL",G16<>0),Q16/ABS(G16),0) | P16: =IF(AND(B16="SELL",D16>0),R16/D16,0) | Q16: =IF(AND(B16="SELL",D16>0,E16>0),(D16/E16)+G16,0) | R16: =IF(B16="SELL",Q16*F16,0) | S16: =S15+R16
A17: 16 | B17: SELL | C17: 45934 | D17: 20000 | E17: 964.8 | F17: 964.8 | G17: -19.39 | I17: 482.79 | J17: 291.858 | K17: =IF(AND(B17="SELL",E17>0,J17<>""),J17/E17,0) | L17: 0.283 | M17: =IF(AND(B17="SELL",L17>0),D17*L17,0) | O17: =IF(AND(B17="SELL",G17<>0),Q17/ABS(G17),0) | P17: =IF(AND(B17="SELL",D17>0),R17/D17,0) | Q17: =IF(AND(B17="SELL",D17>0,E17>0),(D17/E17)+G17,0) | R17: =IF(B17="SELL",Q17*F17,0) | S17: =S16+R17
A18: 17 | B18: SELL | C18: 45934 | D18: 53200 | E18: 964.8 | F18: 964.8 | G18: -51.58 | I18: 431.21 | J18: 291.858 | K18: =IF(AND(B18="SELL",E18>0,J18<>""),J18/E18,0) | L18: 0.283 | M18: =IF(AND(B18="SELL",L18>0),D18*L18,0) | O18: =IF(AND(B18="SELL",G18<>0),Q18/ABS(G18),0) | P18: =IF(AND(B18="SELL",D18>0),R18/D18,0) | Q18: =IF(AND(B18="SELL",D18>0,E18>0),(D18/E18)+G18,0) | R18: =IF(B18="SELL",Q18*F18,0) | S18: =S17+R18
... A28: 27 | B28: SELL | C28: 45938 | D28: 20000 | E28: 964.8 | F28: 964.8 | G28: -19.68 | I28: -177.8 | J28: 297.612 | K28: =IF(AND(B28="SELL",E28>0,J28<>""),J28/E28,0) | L28: 0.293 | M28: =IF(AND(B28="SELL",L28>0),D28*L28,0) | O28: =IF(AND(B28="SELL",G28<>0),Q28/ABS(G28),0) | P28: =IF(AND(B28="SELL",D28>0),R28/D28,0) | Q28: =IF(AND(B28="SELL",D28>0,E28>0),(D28/E28)+G28,0) | R28: =IF(B28="SELL",Q28*F28,0) | S28: =S27+R28
A29: 28 | B29: BUY | C29: 45938 | D29: 998700 | E29: 963 | F29: 963 | G29: 1038.42 | I29: 860.62 | K29: =IF(AND(B29="SELL",E29>0,J29<>""),J29/E29,0) | L29: 0 | M29: =IF(AND(B29="SELL",L29>0),D29*L29,0) | N29: Compra de USDT | O29: =IF(AND(B29="SELL",G29<>0),Q29/ABS(G29),0) | P29: =IF(AND(B29="SELL",D29>0),R29/D29,0) | Q29: =IF(AND(B29="SELL",D29>0,E29>0),(D29/E29)+G29,0) | R29: =IF(B29="SELL",Q29*F29,0) | S29: =S28+R29
A30: 29 | B30: SELL | C30: 45938 | D30: 30000 | E30: 963 | F30: 963 | G30: -29.17 | I30: 831.45 | K30: =IF(AND(B30="SELL",E30>0,J30<>""),J30/E30,0) | L30: 0.000845 | M30: =IF(AND(B30="SELL",L30>0),D30*L30,0) | O30: =IF(AND(B30="SELL",G30<>0),Q30/ABS(G30),0) | P30: =IF(AND(B30="SELL",D30>0),R30/D30,0) | Q30: =IF(AND(B30="SELL",D30>0,E30>0),(D30/E30)+G30,0) | R30: =IF(B30="SELL",Q30*F30,0) | S30: =S29+R30
A31: 30 | B31: SELL | C31: 45938 | D31: 100000 | E31: 963 | F31: 963 | G31: -94.24 | I31: 737.21 | K31: =IF(AND(B31="SELL",E31>0,J31<>""),J31/E31,0) | L31: 0.0172 | M31: =IF(AND(B31="SELL",L31>0),D31*L31,0) | N31: cambio mex | O31: =IF(AND(B31="SELL",G31<>0),Q31/ABS(G31),0) | P31: =IF(AND(B31="SELL",D31>0),R31/D31,0) | Q31: =IF(AND(B31="SELL",D31>0,E31>0),(D31/E31)+G31,0) | R31: =IF(B31="SELL",Q31*F31,0) | S31: =S30+R31
A32: 31 | B32: SELL | C32: 45939 | D32: 25000 | E32: 963 | F32: 963 | G32: -24.51 | I32: 712.7 | J32: 298.8 | K32: =IF(AND(B32="SELL",E32>0,J32<>""),J32/E32,0) | L32: 0.293 | M32: =IF(AND(B32="SELL",L32>0),D32*L32,0) | O32: =IF(AND(B32="SELL",G32<>0),Q32/ABS(G32),0) | P32: =IF(AND(B32="SELL",D32>0),R32/D32,0) | Q32: =IF(AND(B32="SELL",D32>0,E32>0),(D32/E32)+G32,0) | R32: =IF(B32="SELL",Q32*F32,0) | S32: =S31+R32
A33: 32 | B33: SELL | C33: 45939 | D33: 25000 | E33: 963 | F33: 963 | G33: -24.51 | I33: 688.19 | J33: 298.8 | K33: =IF(AND(B33="SELL",E33>0,J33<>""),J33/E33,0) | L33: 0.293 | M33: =IF(AND(B33="SELL",L33>0),D33*L33,0) | O33: =IF(AND(B33="SELL",G33<>0),Q33/ABS(G33),0) | P33: =IF(AND(B33="SELL",D33>0),R33/D33,0) | Q33: =IF(AND(B33="SELL",D33>0,E33>0),(D33/E33)+G33,0) | R33: =IF(B33="SELL",Q33*F33,0) | S33: =S32+R33
A34: 33 | B34: SELL | C34: 45939 | D34: 32700 | E34: 963 | F34: 963 | G34: -32.06 | I34: 656.13 | J34: 298.8 | K34: =IF(AND(B34="SELL",E34>0,J34<>""),J34/E34,0) | L34: 0.293 | M34: =IF(AND(B34="SELL",L34>0),D34*L34,0) | O34: =IF(AND(B34="SELL",G34<>0),Q34/ABS(G34),0) | P34: =IF(AND(B34="SELL",D34>0),R34/D34,0) | Q34: =IF(AND(B34="SELL",D34>0,E34>0),(D34/E34)+G34,0) | R34: =IF(B34="SELL",Q34*F34,0) | S34: =S33+R34
A35: 34 | B35: SELL | C35: 45939 | D35: 100000 | E35: 963 | F35: 963 | G35: -98.05 | I35: 558.08 | J35: 298.8 | K35: =IF(AND(B35="SELL",E35>0,J35<>""),J35/E35,0) | L35: 0.293 | M35: =IF(AND(B35="SELL",L35>0),D35*L35,0) | O35: =IF(AND(B35="SELL",G35<>0),Q35/ABS(G35),0) | P35: =IF(AND(B35="SELL",D35>0),R35/D35,0) | Q35: =IF(AND(B35="SELL",D35>0,E35>0),(D35/E35)+G35,0) | R35: =IF(B35="SELL",Q35*F35,0) | S35: =S34+R35
A36: 35 | B36: SELL | C36: 45939 | D36: 17000 | E36: 963 | F36: 963 | G36: -16.69 | I36: 541.39 | J36: 298.401 | K36: =IF(AND(B36="SELL",E36>0,J36<>""),J36/E36,0) | L36: 0.293 | M36: =IF(AND(B36="SELL",L36>0),D36*L36,0) | O36: =IF(AND(B36="SELL",G36<>0),Q36/ABS(G36),0) | P36: =IF(AND(B36="SELL",D36>0),R36/D36,0) | Q36: =IF(AND(B36="SELL",D36>0,E36>0),(D36/E36)+G36,0) | R36: =IF(B36="SELL",Q36*F36,0) | S36: =S35+R36
A37: 36 | B37: SELL | C37: 45940 | D37: 20000 | E37: 963 | F37: 963 | G37: -19.43 | I37: 521.96 | J37: 298.401 | K37: =IF(AND(B37="SELL",E37>0,J37<>""),J37/E37,0) | L37: 0.29 | M37: =IF(AND(B37="SELL",L37>0),D37*L37,0) | O37: =IF(AND(B37="SELL",G37<>0),Q37/ABS(G37),0) | P37: =IF(AND(B37="SELL",D37>0),R37/D37,0) | Q37: =IF(AND(B37="SELL",D37>0,E37>0),(D37/E37)+G37,0) | R37: =IF(B37="SELL",Q37*F37,0) | S37: =S36+R37
A38: 37 | B38: SELL | C38: 45940 | D38: 30000 | E38: 963 | F38: 963 | G38: -29.15 | I38: 492.81 | J38: 298.401 | K38: =IF(AND(B38="SELL",E38>0,J38<>""),J38/E38,0) | L38: 0.29 | M38: =IF(AND(B38="SELL",L38>0),D38*L38,0) | O38: =IF(AND(B38="SELL",G38<>0),Q38/ABS(G38),0) | P38: =IF(AND(B38="SELL",D38>0),R38/D38,0) | Q38: =IF(AND(B38="SELL",D38>0,E38>0),(D38/E38)+G38,0) | R38: =IF(B38="SELL",Q38*F38,0) | S38: =S37+R38
A39: 38 | B39: SELL | C39: 45940 | D39: 20000 | E39: 963 | F39: 963 | G39: -19.43 | I39: 473.38 | J39: 298.401 | K39: =IF(AND(B39="SELL",E39>0,J39<>""),J39/E39,0) | L39: 0.29 | M39: =IF(AND(B39="SELL",L39>0),D39*L39,0) | O39: =IF(AND(B39="SELL",G39<>0),Q39/ABS(G39),0) | P39: =IF(AND(B39="SELL",D39>0),R39/D39,0) | Q39: =IF(AND(B39="SELL",D39>0,E39>0),(D39/E39)+G39,0) | R39: =IF(B39="SELL",Q39*F39,0) | S39: =S38+R39
A40: 39 | B40: SELL | C40: 45940 | D40: 50000 | E40: 963 | F40: 963 | G40: -48.59 | I40: 424.79 | J40: 298.401 | K40: =IF(AND(B40="SELL",E40>0,J40<>""),J40/E40,0) | L40: 0.29 | M40: =IF(AND(B40="SELL",L40>0),D40*L40,0) | O40: =IF(AND(B40="SELL",G40<>0),Q40/ABS(G40),0) | P40: =IF(AND(B40="SELL",D40>0),R40/D40,0) | Q40: =IF(AND(B40="SELL",D40>0,E40>0),(D40/E40)+G40,0) | R40: =IF(B40="SELL",Q40*F40,0) | S40: =S39+R40
A41: 40 | B41: SELL | C41: 45941 | D41: 30000 | E41: 963 | F41: 963 | G41: -28.71 | I41: 396.08 | J41: 284.5 | K41: =IF(AND(B41="SELL",E41>0,J41<>""),J41/E41,0) | L41: 0.288 | M41: =IF(AND(B41="SELL",L41>0),D41*L41,0) | N41: cambio zuleika | O41: =IF(AND(B41="SELL",G41<>0),Q41/ABS(G41),0) | P41: =IF(AND(B41="SELL",D41>0),R41/D41,0) | Q41: =IF(AND(B41="SELL",D41>0,E41>0),(D41/E41)+G41,0) | R41: =IF(B41="SELL",Q41*F41,0) | S41: =S40+R41
A42: 41 | B42: SELL | C42: 45941 | D42: 50000 | E42: 963 | F42: 963 | G42: -49.93 | I42: 346.15 | J42: 290.35 | K42: =IF(AND(B42="SELL",E42>0,J42<>""),J42/E42,0) | L42: 0.288 | M42: =IF(AND(B42="SELL",L42>0),D42*L42,0) | N42: cambio paula papa | O42: =IF(AND(B42="SELL",G42<>0),Q42/ABS(G42),0) | P42: =IF(AND(B42="SELL",D42>0),R42/D42,0) | Q42: =IF(AND(B42="SELL",D42>0,E42>0),(D42/E42)+G42,0) | R42: =IF(B42="SELL",Q42*F42,0) | S42: =S41+R42
A43: 42 | B43: SELL | C43: 45941 | D43: 90000 | E43: 963 | F43: 963 | G43: -89.25 | I43: 256.9 | J43: 290.401 | K43: =IF(AND(B43="SELL",E43>0,J43<>""),J43/E43,0) | L43: 0.288 | M43: =IF(AND(B43="SELL",L43>0),D43*L43,0) | N43: cambio pinky | O43: =IF(AND(B43="SELL",G43<>0),Q43/ABS(G43),0) | P43: =IF(AND(B43="SELL",D43>0),R43/D43,0) | Q43: =IF(AND(B43="SELL",D43>0,E43>0),(D43/E43)+G43,0) | R43: =IF(B43="SELL",Q43*F43,0) | S43: =S42+R43
A44: 43 | B44: SELL | C44: 45942 | D44: 40000 | E44: 963 | F44: 963 | G44: -39.83 | I44: 442.07 | J44: 288.703 | K44: =IF(AND(B44="SELL",E44>0,J44<>""),J44/E44,0) | L44: 0.2875 | M44: =IF(AND(B44="SELL",L44>0),D44*L44,0) | O44: =IF(AND(B44="SELL",G44<>0),Q44/ABS(G44),0) | P44: =IF(AND(B44="SELL",D44>0),R44/D44,0) | Q44: =IF(AND(B44="SELL",D44>0,E44>0),(D44/E44)+G44,0) | R44: =IF(B44="SELL",Q44*F44,0) | S44: =S43+R44
A45: 44 | B45: SELL | C45: 45942 | D45: 40000 | E45: 963 | F45: 963 | G45: -39.87 | I45: 402.2 | J45: 288.4 | K45: =IF(AND(B45="SELL",E45>0,J45<>""),J45/E45,0) | L45: 0.2875 | M45: =IF(AND(B45="SELL",L45>0),D45*L45,0) | O45: =IF(AND(B45="SELL",G45<>0),Q45/ABS(G45),0) | P45: =IF(AND(B45="SELL",D45>0),R45/D45,0) | Q45: =IF(AND(B45="SELL",D45>0,E45>0),(D45/E45)+G45,0) | R45: =IF(B45="SELL",Q45*F45,0) | S45: =S44+R45
A46: 45 | B46: SELL | C46: 45943 | D46: 40000 | E46: 963 | F46: 963 | G46: -39.63 | I46: 362.57 | J46: 289.662 | K46: =IF(AND(B46="SELL",E46>0,J46<>""),J46/E46,0) | L46: 0.287 | M46: =IF(AND(B46="SELL",L46>0),D46*L46,0) | O46: =IF(AND(B46="SELL",G46<>0),Q46/ABS(G46),0) | P46: =IF(AND(B46="SELL",D46>0),R46/D46,0) | Q46: =IF(AND(B46="SELL",D46>0,E46>0),(D46/E46)+G46,0) | R46: =IF(B46="SELL",Q46*F46,0) | S46: =S45+R46
A47: 46 | B47: SELL | C47: 45943 | D47: 25000 | E47: 963 | F47: 963 | G47: -24.69 | I47: 337.88 | J47: 290.57 | K47: =IF(AND(B47="SELL",E47>0,J47<>""),J47/E47,0) | L47: 0.287 | M47: =IF(AND(B47="SELL",L47>0),D47*L47,0) | O47: =IF(AND(B47="SELL",G47<>0),Q47/ABS(G47),0) | P47: =IF(AND(B47="SELL",D47>0),R47/D47,0) | Q47: =IF(AND(B47="SELL",D47>0,E47>0),(D47/E47)+G47,0) | R47: =IF(B47="SELL",Q47*F47,0) | S47: =S46+R47
A48: 47 | B48: SELL | C48: 45943 | D48: 25000 | E48: 963 | F48: 963 | G48: -24.41 | I48: 313.47 | J48: 293.8565 | K48: =IF(AND(B48="SELL",E48>0,J48<>""),J48/E48,0) | L48: 0.287 | M48: =IF(AND(B48="SELL",L48>0),D48*L48,0) | O48: =IF(AND(B48="SELL",G48<>0),Q48/ABS(G48),0) | P48: =IF(AND(B48="SELL",D48>0),R48/D48,0) | Q48: =IF(AND(B48="SELL",D48>0,E48>0),(D48/E48)+G48,0) | R48: =IF(B48="SELL",Q48*F48,0) | S48: =S47+R48
A49: 48 | B49: SELL | C49: 45944 | D49: 35100 | E49: 963 | F49: 963 | G49: -34.31 | I49: 279.16 | J49: 294.5 | K49: =IF(AND(B49="SELL",E49>0,J49<>""),J49/E49,0) | L49: 0.288 | M49: =IF(AND(B49="SELL",L49>0),D49*L49,0) | O49: =IF(AND(B49="SELL",G49<>0),Q49/ABS(G49),0) | P49: =IF(AND(B49="SELL",D49>0),R49/D49,0) | Q49: =IF(AND(B49="SELL",D49>0,E49>0),(D49/E49)+G49,0) | R49: =IF(B49="SELL",Q49*F49,0) | S49: =S48+R49
...

Sheet Noviembre 2025
A1: N° | B1: Tipo | C1: Fecha | D1: Monto CLP | E1: USDT/CLP Compra | F1: USDT/CLP Venta | G1: USDT Mov | H1: Tax Binance | I1: Capital USDT | J1: Tasa Destino | K1: Tasa Real | L1: Tasa IREMI | M1: Valor Destino | N1: Comentario | O1: % G USDT | P1: % G CLP | Q1: Ganancia USDT | R1: Ganancia CLP | S1: Acumulado SELL
A2: 1 | B2: SELL | C2: 45961 | D2: 50000 | E2: 946.22 | F2: 946.22 | G2: -50.66 | I2: 599.8 | J2: 298.01 | K2: =IF(AND(B2="SELL",E2>0,J2<>""),J2/E2,0) | L2: 0.302 | M2: =IF(AND(B2="SELL",L2>0),D2*L2,0) | O2: =IF(AND(B2="SELL",G2<>0),Q2/ABS(G2),0) | P2: =IF(AND(B2="SELL",D2>0),R2/D2,0) | Q2: =IF(AND(B2="SELL",D2>0,E2>0),(D2/E2)+G2,0) | R2: =IF(B2="SELL",Q2*F2,0) | S2: ='Octubre 2025'!S110+R2
A3: 2 | B3: SELL | C3: 45962 | D3: 137000 | E3: 946.22 | F3: 946.22 | G3: -137.06 | I3: 462.74 | J3: 296.85 | K3: =IF(AND(B3="SELL",E3>0,J3<>""),J3/E3,0) | L3: 0.297 | M3: =IF(AND(B3="SELL",L3>0),D3*L3,0) | N3: Cambio uvida y francisco | O3: =IF(AND(B3="SELL",G3<>0),Q3/ABS(G3),0) | P3: =IF(AND(B3="SELL",D3>0),R3/D3,0) | Q3: =IF(AND(B3="SELL",D3>0,E3>0),(D3/E3)+G3,0) | R3: =IF(B3="SELL",Q3*F3,0) | S3: =S2+R3
A4: 3 | B4: SELL | C4: 45962 | D4: 40000 | E4: 946.22 | F4: 946.22 | G4: -39.77 | I4: 422.97 | J4: 298.66 | K4: =IF(AND(B4="SELL",E4>0,J4<>""),J4/E4,0) | L4: 0.297 | M4: =IF(AND(B4="SELL",L4>0),D4*L4,0) | N4: cambio angel | O4: =IF(AND(B4="SELL",G4<>0),Q4/ABS(G4),0) | P4: =IF(AND(B4="SELL",D4>0),R4/D4,0) | Q4: =IF(AND(B4="SELL",D4>0,E4>0),(D4/E4)+G4,0) | R4: =IF(B4="SELL",Q4*F4,0) | S4: =S3+R4
A5: 4 | B5: SELL | C5: 45962 | D5: 30000 | E5: 946.22 | F5: 946.22 | G5: -30.01 | I5: 392.96 | J5: 296.85 | K5: =IF(AND(B5="SELL",E5>0,J5<>""),J5/E5,0) | L5: 0.297 | M5: =IF(AND(B5="SELL",L5>0),D5*L5,0) | O5: =IF(AND(B5="SELL",G5<>0),Q5/ABS(G5),0) | P5: =IF(AND(B5="SELL",D5>0),R5/D5,0) | Q5: =IF(AND(B5="SELL",D5>0,E5>0),(D5/E5)+G5,0) | R5: =IF(B5="SELL",Q5*F5,0) | S5: =S4+R5
A6: 5 | B6: SELL | C6: 45962 | D6: 15000 | E6: 946.22 | F6: 946.22 | G6: -15.11 | I6: 377.85 | J6: 294.7 | K6: =IF(AND(B6="SELL",E6>0,J6<>""),J6/E6,0) | L6: 0.297 | M6: =IF(AND(B6="SELL",L6>0),D6*L6,0) | O6: =IF(AND(B6="SELL",G6<>0),Q6/ABS(G6),0) | P6: =IF(AND(B6="SELL",D6>0),R6/D6,0) | Q6: =IF(AND(B6="SELL",D6>0,E6>0),(D6/E6)+G6,0) | R6: =IF(B6="SELL",Q6*F6,0) | S6: =S5+R6
A7: 6 | B7: SELL | C7: 45963 | D7: 30000 | E7: 946.22 | F7: 946.22 | G7: -30.4 | I7: 347.45 | J7: 296.023 | K7: =IF(AND(B7="SELL",E7>0,J7<>""),J7/E7,0) | L7: 0.3 | M7: =IF(AND(B7="SELL",L7>0),D7*L7,0) | O7: =IF(AND(B7="SELL",G7<>0),Q7/ABS(G7),0) | P7: =IF(AND(B7="SELL",D7>0),R7/D7,0) | Q7: =IF(AND(B7="SELL",D7>0,E7>0),(D7/E7)+G7,0) | R7: =IF(B7="SELL",Q7*F7,0) | S7: =S6+R7
A8: 7 | B8: SELL | C8: 45964 | D8: 20000 | E8: 946.22 | F8: 946.22 | G8: -20.06 | I8: 327.39 | J8: 297.5 | K8: =IF(AND(B8="SELL",E8>0,J8<>""),J8/E8,0) | L8: 0.2985 | M8: =IF(AND(B8="SELL",L8>0),D8*L8,0) | O8: =IF(AND(B8="SELL",G8<>0),Q8/ABS(G8),0) | P8: =IF(AND(B8="SELL",D8>0),R8/D8,0) | Q8: =IF(AND(B8="SELL",D8>0,E8>0),(D8/E8)+G8,0) | R8: =IF(B8="SELL",Q8*F8,0) | S8: =S7+R8
A9: 8 | B9: SELL | C9: 45965 | D9: 140000 | E9: 946.22 | F9: 946.22 | G9: -139.33 | I9: 188.06 | J9: 307.46 | K9: =IF(AND(B9="SELL",E9>0,J9<>""),J9/E9,0) | L9: 0.306 | M9: =IF(AND(B9="SELL",L9>0),D9*L9,0) | O9: =IF(AND(B9="SELL",G9<>0),Q9/ABS(G9),0) | P9: =IF(AND(B9="SELL",D9>0),R9/D9,0) | Q9: =IF(AND(B9="SELL",D9>0,E9>0),(D9/E9)+G9,0) | R9: =IF(B9="SELL",Q9*F9,0) | S9: =S8+R9
A10: 9 | B10: SELL | C10: 45965 | D10: 50000 | E10: 946.22 | F10: 946.22 | G10: -51.03 | I10: 137.03 | J10: 299.5 | K10: =IF(AND(B10="SELL",E10>0,J10<>""),J10/E10,0) | L10: 0.306 | M10: =IF(AND(B10="SELL",L10>0),D10*L10,0) | O10: =IF(AND(B10="SELL",G10<>0),Q10/ABS(G10),0) | P10: =IF(AND(B10="SELL",D10>0),R10/D10,0) | Q10: =IF(AND(B10="SELL",D10>0,E10>0),(D10/E10)+G10,0) | R10: =IF(B10="SELL",Q10*F10,0) | S10: =S9+R10
A11: 10 | B11: SELL | C11: 45965 | D11: 15000 | E11: 946.22 | F11: 946.22 | G11: -15.14 | I11: 121.89 | J11: 303.011 | K11: =IF(AND(B11="SELL",E11>0,J11<>""),J11/E11,0) | L11: 0.306 | M11: =IF(AND(B11="SELL",L11>0),D11*L11,0) | O11: =IF(AND(B11="SELL",G11<>0),Q11/ABS(G11),0) | P11: =IF(AND(B11="SELL",D11>0),R11/D11,0) | Q11: =IF(AND(B11="SELL",D11>0,E11>0),(D11/E11)+G11,0) | R11: =IF(B11="SELL",Q11*F11,0) | S11: =S10+R11
A12: 11 | B12: SELL | C12: 45965 | D12: 40000 | E12: 946.22 | F12: 946.22 | G12: -40.15 | I12: 81.74 | J12: 304.81 | K12: =IF(AND(B12="SELL",E12>0,J12<>""),J12/E12,0) | L12: 0.306 | M12: =IF(AND(B12="SELL",L12>0),D12*L12,0) | O12: =IF(AND(B12="SELL",G12<>0),Q12/ABS(G12),0) | P12: =IF(AND(B12="SELL",D12>0),R12/D12,0) | Q12: =IF(AND(B12="SELL",D12>0,E12>0),(D12/E12)+G12,0) | R12: =IF(B12="SELL",Q12*F12,0) | S12: =S11+R12
A13: 12 | B13: SELL | C13: 45965 | D13: 50000 | E13: 946.22 | F13: 946.22 | G13: -49.62 | I13: 32.12 | J13: 3.375 | K13: =IF(AND(B13="SELL",E13>0,J13<>""),J13/E13,0) | L13: 0.00336 | M13: =IF(AND(B13="SELL",L13>0),D13*L13,0) | O13: =IF(AND(B13="SELL",G13<>0),Q13/ABS(G13),0) | P13: =IF(AND(B13="SELL",D13>0),R13/D13,0) | Q13: =IF(AND(B13="SELL",D13>0,E13>0),(D13/E13)+G13,0) | R13: =IF(B13="SELL",Q13*F13,0) | S13: =S12+R13
A14: 13 | B14: SELL | C14: 45965 | D14: 30000 | E14: 946.22 | F14: 946.22 | G14: -30 | I14: 2.12 | J14: 305.902 | K14: =IF(AND(B14="SELL",E14>0,J14<>""),J14/E14,0) | L14: 0.306 | M14: =IF(AND(B14="SELL",L14>0),D14*L14,0) | O14: =IF(AND(B14="SELL",G14<>0),Q14/ABS(G14),0) | P14: =IF(AND(B14="SELL",D14>0),R14/D14,0) | Q14: =IF(AND(B14="SELL",D14>0,E14>0),(D14/E14)+G14,0) | R14: =IF(B14="SELL",Q14*F14,0) | S14: =S13+R14
A15: 14 | B15: SELL | C15: 45965 | D15: 30000 | E15: 946.22 | F15: 946.22 | G15: -29.78 | I15: -27.66 | J15: 308.15 | K15: =IF(AND(B15="SELL",E15>0,J15<>""),J15/E15,0) | L15: 0.306 | M15: =IF(AND(B15="SELL",L15>0),D15*L15,0) | O15: =IF(AND(B15="SELL",G15<>0),Q15/ABS(G15),0) | P15: =IF(AND(B15="SELL",D15>0),R15/D15,0) | Q15: =IF(AND(B15="SELL",D15>0,E15>0),(D15/E15)+G15,0) | R15: =IF(B15="SELL",Q15*F15,0) | S15: =S14+R15
A16: 15 | B16: SELL | C16: 45965 | D16: 30000 | E16: 946.22 | F16: 946.22 | G16: -29.8 | I16: -57.46 | J16: 308.05 | K16: =IF(AND(B16="SELL",E16>0,J16<>""),J16/E16,0) | L16: 0.306 | M16: =IF(AND(B16="SELL",L16>0),D16*L16,0) | O16: =IF(AND(B16="SELL",G16<>0),Q16/ABS(G16),0) | P16: =IF(AND(B16="SELL",D16>0),R16/D16,0) | Q16: =IF(AND(B16="SELL",D16>0,E16>0),(D16/E16)+G16,0) | R16: =IF(B16="SELL",Q16*F16,0) | S16: =S15+R16
